Workbook

Sheet Refined Data
A1: Date | B1: DBH (m) | C1: method | D1: Height (m) | E1: GT DBH (m) | F1: GT Height (m) | G1: latitude | H1: longitude | I1: user_id | J1: DBH Height (m) | K1: phone_model | L1: app_version | M1: Species # | N1: Tree # | O1: Stem # | P1: Footprint | Q1: Edits? | R1: notes | S1: project | T1: Species | U1: dbh_photo_url | V1: height_photo_url | W1: dmap_zip_url | X1: trunk_occupancy | Y1: trunk_dist_m | Z1: apparent_dbh_med_m | AA1: measurement_id
A2: 2026_03_09 19:43:00 | B2: 0.84479812 | C2: ADM Fixed Percent | D2: 7.8200092 | E2: 0.831 | F2: 22.8 | G2: 35.310332 | H2: -120.66261 | I2: W3HjVEeEFWXa94BMF8iP5lQOZU03 | J2: 0.24012093 | K2: iPhone13,3 | L2: 2.3.3 | M2: 1 | N2: 1 | O2: 1 | R2: Redwood tree 1 | S2: W25 inventory | T2: coast redwood | U2: https://firebasestorage.googleapis.com/v0/b/wt-foundation-production.appspot.com/o/measurements%2FMeasureMethod.ADM_FIXED_PCT%2FdbhPhoto%2F1773768455780?alt=media&token=8918caa2-020e-47a3-ac4c-54d6e7bcb77a | V2: https://firebasestorage.googleapis.com/v0/b/wt-foundation-production.appspot.com/o/measurements%2FMeasureMethod.ADM_FIXED_PCT%2FheightPhoto%2F1773768049361?alt=media&token=bc77bd00-be6f-4a1b-bf6e-b966ca8952f8 | W2: https://firebasestorage.googleapis.com/v0/b/wt-foundation-production.appspot.com/o/measurements%2FMeasureMethod.ADM_FIXED_PCT%2Fdepth%2F1773768496664?alt=media&token=24c10cc4-7c54-4cb7-adaf-c457cba1dd09 | X2: 0.2349537 | Y2: 3.3041654 | Z2: 0.75691559 | AA2: iFocDDPUhG9WdHAlaByf | AC2: Total Trees Measured:
A3: 2026_03_09 19:53:18 | B3: 0.76811854 | C3: ADM Fixed Percent | D3: 18.111691 | E3: 0.85 | F3: 22.7 | G3: 35.309617 | H3: -120.66291 | I3: W3HjVEeEFWXa94BMF8iP5lQOZU03 | J3: 1.1512799 | K3: iPhone13,3 | L3: 2.3.3 | M3: 1 | N3: 2 | O3: 1 | R3: Redwood tree 2 stem 1 | S3: W25 inventory | T3: coast redwood | U3: https://firebasestorage.googleapis.com/v0/b/wt-foundation-production.appspot.com/o/measurements%2FMeasureMethod.ADM_FIXED_PCT%2FdbhPhoto%2F1773300400017?alt=media&token=1bee9cc3-f974-469a-91e0-6165d82f671f | V3: https://firebasestorage.googleapis.com/v0/b/wt-foundation-production.appspot.com/o/measurements%2FMeasureMethod.ADM_FIXED_PCT%2FheightPhoto%2F1773300399955?alt=media&token=166c182a-e0fd-4ed6-aa9b-015fd4e76059 | W3: https://firebasestorage.googleapis.com/v0/b/wt-foundation-production.appspot.com/o/measurements%2FMeasureMethod.ADM_FIXED_PCT%2Fdepth%2F1773768353454?alt=media&token=94f616c2-2003-4965-8d7c-a179755ae178 | X3: 0.23697917 | Y3: 3.0167775 | Z3: 0.68789351 | AA3: z4rH3lRn5assScP9rcXd | AC3: =COUNTIF(O:O,"1") -> 78
A4: 2026_03_09 20:02:32 | B4: 0.29198 | C4: ADM Fixed Percent | D4: 10.816227 | E4: 0.312 | F4: 12.8 | G4: 35.310164 | H4: -120.66273 | I4: W3HjVEeEFWXa94BMF8iP5lQOZU03 | J4: 1.1533961 | K4: iPhone13,3 | L4: 2.3.3 | M4: 1 | N4: 3 | O4: 1 | R4: Redwood tree 3 | S4: W25 inventory | T4: coast redwood | U4: https://firebasestorage.googleapis.com/v0/b/wt-foundation-production.appspot.com/o/measurements%2FMeasureMethod.ADM_FIXED_PCT%2FdbhPhoto%2F1773768429721?alt=media&token=b57c2e2d-da85-4d34-8131-1ebd5b0518dd | V4: https://firebasestorage.googleapis.com/v0/b/wt-foundation-production.appspot.com/o/measurements%2FMeasureMethod.ADM_FIXED_PCT%2FheightPhoto%2F1773768422775?alt=media&token=1584bb56-ed98-4c26-bdaa-3c369f039c78 | W4: https://firebasestorage.googleapis.com/v0/b/wt-foundation-production.appspot.com/o/measurements%2FMeasureMethod.ADM_FIXED_PCT%2Fdepth%2F1773768499473?alt=media&token=9cea7eee-df5e-46c9-b326-a5be08fc1f7f | X4: 0.22395833 | Y4: 1.1227289 | Z4: 0.26205472 | AA4: IQicm8hybxWTbCtLK9oc
A5: 2026_03_09 20:07:59 | B5: 0.40847131 | C5: ADM Fixed Percent | D5: 15.771734 | E5: 0.409 | F5: 13.4 | G5: 35.309597 | H5: -120.6629 | I5: W3HjVEeEFWXa94BMF8iP5lQOZU03 | J5: 1.2906859 | K5: iPhone13,3 | L5: 2.3.3 | M5: 1 | N5: 4 | O5: 1 | R5: Redwood tree 4 | S5: W25 inventory | T5: coast redwood | U5: https://firebasestorage.googleapis.com/v0/b/wt-foundation-production.appspot.com/o/measurements%2FMeasureMethod.ADM_FIXED_PCT%2FdbhPhoto%2F1773768535469?alt=media&token=bc55fa73-8e3c-47f8-958d-c4e41701629a | V5: https://firebasestorage.googleapis.com/v0/b/wt-foundation-production.appspot.com/o/measurements%2FMeasureMethod.ADM_FIXED_PCT%2FheightPhoto%2F1773768525865?alt=media&token=ac4b7cba-f743-4c9e-8edd-d2b177514da7 | W5: https://firebasestorage.googleapis.com/v0/b/wt-foundation-production.appspot.com/o/measurements%2FMeasureMethod.ADM_FIXED_PCT%2Fdepth%2F1773772765887?alt=media&token=79234272-5c37-4636-bd01-b6cfc6d9df73 | X5: 0.22395833 | Y5: 1.5503239 | Z5: 0.36633294 | AA5: 0rlV6XffgjeEBQUgddMJ | AD5: =SUMPRODUCT(($T$2:$T$99=$AE5) * (1/COUNTIFS($T$2:$T$99,$T$2:$T$99,$N$2:$N$99,$N$2:$N$99))) -> 10 | AE5: coast redwood
A6: 2026_03_09 20:10:45 | B6: 0.55843698 | C6: ADM Fixed Percent | D6: 17.006998 | E6: 0.539 | F6: 15.7 | G6: 35.309467 | H6: -120.66279 | I6: W3HjVEeEFWXa94BMF8iP5lQOZU03 | J6: 1.4203527 | K6: iPhone13,3 | L6: 2.3.3 | M6: 1 | N6: 5 | O6: 1 | R6: Redwood tree 5 | S6: W25 inventory | T6: coast redwood | U6: https://firebasestorage.googleapis.com/v0/b/wt-foundation-production.appspot.com/o/measurements%2FMeasureMethod.ADM_FIXED_PCT%2FdbhPhoto%2F1773385405582?alt=media&token=7eeccff5-93c9-469c-bf8b-0292397de16a | V6: https://firebasestorage.googleapis.com/v0/b/wt-foundation-production.appspot.com/o/measurements%2FMeasureMethod.ADM_FIXED_PCT%2FheightPhoto%2F1773385405570?alt=media&token=1a3ec410-cdac-4173-8581-cfa35be07915 | W6: https://firebasestorage.googleapis.com/v0/b/wt-foundation-production.appspot.com/o/measurements%2FMeasureMethod.ADM_FIXED_PCT%2Fdepth%2F1773772825421?alt=media&token=19ba0938-a305-47b9-9408-abb53cd3de6e | X6: 0.22539194 | Y6: 2.1358037 | Z6: 0.50112373 | AA6: dkrFdzZ2l90gQsvfvd4X | AD6: =SUMPRODUCT(($T$2:$T$99=$AE6) * (1/COUNTIFS($T$2:$T$99,$T$2:$T$99,$N$2:$N$99,$N$2:$N$99))) -> 24 | AE6: coastal live oak
A7: 2026_03_09 20:24:21 | B7: 0.74107102 | C7: ADM Fixed Percent | D7: 12.301169 | E7: 0.782 | F7: 22.8 | G7: 35.30963 | H7: -120.66293 | I7: W3HjVEeEFWXa94BMF8iP5lQOZU03 | J7: 1.0590056 | K7: iPhone13,3 | L7: 2.3.3 | M7: 1 | N7: 7 | O7: 1 | R7: redwood tree 7 | S7: W25 inventory | T7: coast redwood | U7: https://firebasestorage.googleapis.com/v0/b/wt-foundation-production.appspot.com/o/measurements%2FMeasureMethod.ADM_FIXED_PCT%2FdbhPhoto%2F1773857389672?alt=media&token=35bf63b1-c8bc-452b-967a-f8b840ac6f1c | V7: https://firebasestorage.googleapis.com/v0/b/wt-foundation-production.appspot.com/o/measurements%2FMeasureMethod.ADM_FIXED_PCT%2FheightPhoto%2F1773857384551?alt=media&token=0d819d37-fa36-429e-87d7-d72ab81b1403 | W7: https://firebasestorage.googleapis.com/v0/b/wt-foundation-production.appspot.com/o/measurements%2FMeasureMethod.ADM_FIXED_PCT%2Fdepth%2F1773895829950?alt=media&token=91b9f13d-8860-478f-bf67-cecb2a95be6b | X7: 0.22983186 | Y7: 2.8659631 | Z7: 0.66438344 | AA7: aPlpmRMWgiVNHCx7vien | AD7: =SUMPRODUCT(($T$2:$T$99=$AE7) * (1/COUNTIFS($T$2:$T$99,$T$2:$T$99,$N$2:$N$99,$N$2:$N$99))) -> 5 | AE7: engelmann oak
A8: 2026_03_09 20:32:43 | B8: 0.25306193 | C8: ADM Fixed Percent | D8: 22.717957 | E8: 0.312 | F8: 19.2 | G8: 35.309642 | H8: -120.66294 | I8: W3HjVEeEFWXa94BMF8iP5lQOZU03 | J8: 1.8705394 | K8: iPhone13,3 | L8: 2.3.3 | M8: 1 | N8: 8 | O8: 1 | R8: redwood tree 8 stem 1 | S8: W25 inventory | T8: coast redwood | U8: https://firebasestorage.googleapis.com/v0/b/wt-foundation-production.appspot.com/o/measurements%2FMeasureMethod.ADM_FIXED_PCT%2FdbhPhoto%2F1773895938390?alt=media&token=b4d0b648-5312-4f12-90cf-5b36478bb617 | V8: https://firebasestorage.googleapis.com/v0/b/wt-foundation-production.appspot.com/o/measurements%2FMeasureMethod.ADM_FIXED_PCT%2FheightPhoto%2F1773895917790?alt=media&token=4a3bdab4-fc55-4f58-bd3d-364c644507bd | W8: https://firebasestorage.googleapis.com/v0/b/wt-foundation-production.appspot.com/o/measurements%2FMeasureMethod.ADM_FIXED_PCT%2Fdepth%2F1773895960152?alt=media&token=ac4a7445-c880-491d-9980-6503faaa97f7 | X8: 0.23883929 | Y8: 1.0719571 | Z8: 0.22703288 | AA8: sE272u19EfYvn49nPWjN | AD8: =SUMPRODUCT(($T$2:$T$99=$AE8) * (1/COUNTIFS($T$2:$T$99,$T$2:$T$99,$N$2:$N$99,$N$2:$N$99))) -> 2 | AE8: white alder
A9: 2026_03_09 20:33:44 | B9: 0.46266606 | C9: ADM Fixed Percent | D9: 10.746271 | E9: 0.519 | F9: 19.2 | G9: 35.310248 | H9: -120.66262 | I9: W3HjVEeEFWXa94BMF8iP5lQOZU03 | J9: 0.73293602 | K9: iPhone13,3 | L9: 2.3.3 | M9: 1 | N9: 8 | O9: 2 | R9: redwood tree 8 stem 2 | S9: W25 inventory | T9: coast redwood | U9: https://firebasestorage.googleapis.com/v0/b/wt-foundation-production.appspot.com/o/measurements%2FMeasureMethod.ADM_FIXED_PCT%2FdbhPhoto%2F1773895983446?alt=media&token=15ae0a53-975f-4e59-8a7a-0187bcedab2f | V9: https://firebasestorage.googleapis.com/v0/b/wt-foundation-production.appspot.com/o/measurements%2FMeasureMethod.ADM_FIXED_PCT%2FheightPhoto%2F1773895978171?alt=media&token=6c6c769a-f3ff-430e-b28c-c1a0af819e93 | W9: https://firebasestorage.googleapis.com/v0/b/wt-foundation-production.appspot.com/o/measurements%2FMeasureMethod.ADM_FIXED_PCT%2Fdepth%2F1773895989396?alt=media&token=56d6dac9-ed62-4103-a5bb-03f8fee67e6f | X9: 0.22421875 | Y9: 1.8091028 | Z9: 0.41484218 | AA9: DTlvOXkT8bv25o8CG2lH | AD9: =SUMPRODUCT(($T$2:$T$99=$AE9) * (1/COUNTIFS($T$2:$T$99,$T$2:$T$99,$N$2:$N$99,$N$2:$N$99))) -> 1 | AE9: california laurel
A10: 2026_03_11 20:39:56 | C10: ADM Fixed Percent | D10: 6.6830125 | F10: 6.2 | G10: 35.309606 | H10: -120.66294 | I10: W3HjVEeEFWXa94BMF8iP5lQOZU03 | J10: 0.99732733 | K10: iPhone13,3 | L10: 2.4.2 | M10: 1 | N10: 9 | O10: 0 | R10: caution tape tree | S10: W25 inventory | T10: coast redwood | U10: https://firebasestorage.googleapis.com/v0/b/wt-foundation-production.appspot.com/o/measurements%2FMeasureMethod.ADM_FIXED_PCT%2FdbhPhoto%2F1773896006235?alt=media&token=dbf45a7f-40e1-45b6-9066-1b5f2c3275f8 | V10: https://firebasestorage.googleapis.com/v0/b/wt-foundation-production.appspot.com/o/measurements%2FMeasureMethod.ADM_FIXED_PCT%2FheightPhoto%2F1773895993952?alt=media&token=0c2678d2-373b-47be-bc56-187390c56baa | W10: https://firebasestorage.googleapis.com/v0/b/wt-foundation-production.appspot.com/o/measurements%2FMeasureMethod.ADM_FIXED_PCT%2Fdepth%2F1773896024224?alt=media&token=b6b2f2b1-5089-4800-8226-583ad90b1862 | X10: 0.28893849 | Y10: 0.54839748 | Z10: 0.05095318 | AA10: HdCJTUZkkb8yXqwaNvq7 | AD10: =SUMPRODUCT(($T$2:$T$99=$AE10) * (1/COUNTIFS($T$2:$T$99,$T$2:$T$99,$N$2:$N$99,$N$2:$N$99))) -> 1 | AE10: california sycamore
A11: 2026_03_11 21:10:35 | B11: 0.51640786 | C11: ADM Fixed Percent | D11: 15.999005 | E11: 0.565 | F11: 16.2 | G11: 35.309473 | H11: -120.66287 | I11: W3HjVEeEFWXa94BMF8iP5lQOZU03 | J11: 1.4232583 | K11: iPhone13,3 | L11: 2.4.2 | M11: 1 | N11: 10 | O11: 1 | R11: redwood 10 | S11: W25 inventory | T11: coast redwood | U11: https://firebasestorage.googleapis.com/v0/b/wt-foundation-production.appspot.com/o/measurements%2FMeasureMethod.ADM_FIXED_PCT%2FdbhPhoto%2F1773896055828?alt=media&token=d22aff70-a439-422c-bbd0-657d40d59a0a | V11: https://firebasestorage.googleapis.com/v0/b/wt-foundation-production.appspot.com/o/measurements%2FMeasureMethod.ADM_FIXED_PCT%2FheightPhoto%2F1773896046697?alt=media&token=9c3f0ba6-b124-42a5-ae7e-ebc7a87bcf85 | W11: https://firebasestorage.googleapis.com/v0/b/wt-foundation-production.appspot.com/o/measurements%2FMeasureMethod.ADM_FIXED_PCT%2Fdepth%2F1773896064829?alt=media&token=7248e7be-e735-4330-85c5-f5e5bcdb491c | X11: 0.24110243 | Y11: 2.0302442 | Z11: 0.46543863 | AA11: HB2mh4gtpgGvCbr4d801 | AD11: =SUMPRODUCT(($T$2:$T$99=$AE11) * (1/COUNTIFS($T$2:$T$99,$T$2:$T$99,$N$2:$N$99,$N$2:$N$99))) -> 1 | AE11: monterey cypress
A12: 2026_03_11 21:18:25 | B12: 0.3570972 | C12: ADM Fixed Percent | D12: 16.708858 | E12: 0.581 | F12: 17.2 | G12: 35.309611 | H12: -120.66296 | I12: W3HjVEeEFWXa94BMF8iP5lQOZU03 | J12: 1.059845 | K12: iPhone13,3 | L12: 2.4.2 | M12: 1 | N12: 11 | O12: 1 | R12: redwood 11 | S12: W25 inventory | T12: coast redwood | U12: https://firebasestorage.googleapis.com/v0/b/wt-foundation-production.appspot.com/o/measurements%2FMeasureMethod.ADM_FIXED_PCT%2FdbhPhoto%2F1773896093687?alt=media&token=ba4ba541-fe82-4a7a-bf02-75678f8cc29c | V12: https://firebasestorage.googleapis.com/v0/b/wt-foundation-production.appspot.com/o/measurements%2FMeasureMethod.ADM_FIXED_PCT%2FheightPhoto%2F1773896078713?alt=media&token=988c920e-c20e-45cb-bfae-603072ec0cbe | W12: https://firebasestorage.googleapis.com/v0/b/wt-foundation-production.appspot.com/o/measurements%2FMeasureMethod.ADM_FIXED_PCT%2Fdepth%2F1773896106806?alt=media&token=9d1e904b-6683-46e0-bcab-7c76b1e879ad | X12: 0.26328125 | Y12: 2.0221908 | Z12: 0.45933714 | AA12: F1dpH5GfFqAOnIxWIGKb | AD12: =SUMPRODUCT(($T$2:$T$99=$AE12) * (1/COUNTIFS($T$2:$T$99,$T$2:$T$99,$N$2:$N$99,$N$2:$N$99))) -> 1 | AE12: unknown
A13: 2026_03_17 15:38:11 | B13: 0.35948566 | C13: ADM Fixed Percent | D13: 12.241009 | E13: 0.387 | F13: 13.2 | G13: 35.310337 | H13: -120.66298 | I13: W3HjVEeEFWXa94BMF8iP5lQOZU03 | J13: 1.3288232 | K13: iPhone13,3 | L13: 2.4.2 | M13: 2 | N13: 1 | O13: 1 | R13: TREE 1 QUAG stem 1 | S13: W25 inventory | T13: coastal live oak | U13: https://firebasestorage.googleapis.com/v0/b/wt-foundation-production.appspot.com/o/measurements%2FMeasureMethod.ADM_FIXED_PCT%2FdbhPhoto%2F1773896122238?alt=media&token=beb517a7-15a1-4e16-a0c6-5b414a4e0f7d | V13: https://firebasestorage.googleapis.com/v0/b/wt-foundation-production.appspot.com/o/measurements%2FMeasureMethod.ADM_FIXED_PCT%2FheightPhoto%2F1773896116710?alt=media&token=ea46caa3-c378-478f-8160-7efd3a5364ff | W13: https://firebasestorage.googleapis.com/v0/b/wt-foundation-production.appspot.com/o/measurements%2FMeasureMethod.ADM_FIXED_PCT%2Fdepth%2F1773896128224?alt=media&token=c9fb6799-ee1d-47c1-a416-38af36859577 | X13: 0.23494337 | Y13: 1.3611382 | Z13: 0.32239594 | AA13: V9hCX1ewKAhW6TVvhkr7 | AD13: =SUM(AD11:AD12) -> 2
A14: 2026_03_17 15:39:41 | B14: 0.13822588 | C14: ADM Fixed Percent | D14: 0.90940702 | E14: 0.144 | F14: 0.95 | G14: 35.310288 | H14: -120.66291 | I14: W3HjVEeEFWXa94BMF8iP5lQOZU03 | J14: 1.2248132 | K14: iPhone13,3 | L14: 2.4.2 | M14: 2 | N14: 1 | O14: 2 | R14: stem 2 | S14: W25 inventory | T14: coastal live oak | U14: https://firebasestorage.googleapis.com/v0/b/wt-foundation-production.appspot.com/o/measurements%2FMeasureMethod.ADM_FIXED_PCT%2FdbhPhoto%2F1773896151418?alt=media&token=ce067017-2173-4c45-bf06-831706a135df | V14: https://firebasestorage.googleapis.com/v0/b/wt-foundation-production.appspot.com/o/measurements%2FMeasureMethod.ADM_FIXED_PCT%2FheightPhoto%2F1773896143908?alt=media&token=b9cda55f-d757-40da-aaec-f31e83fa3f63 | W14: https://firebasestorage.googleapis.com/v0/b/wt-foundation-production.appspot.com/o/measurements%2FMeasureMethod.ADM_FIXED_PCT%2Fdepth%2F1773896160637?alt=media&token=7acdb7e2-5db0-4c94-ad2f-c7e0ebf6ccf4 | X14: 0.23611111 | Y14: 0.51099956 | Z14: 0.12405359 | AA14: CWX9Sd8UjwyAuICAXb0j
A15: 2026_03_17 16:35:20 | B15: 0.41157525 | C15: ADM Fixed Percent | D15: 13.914988 | E15: 0.45 | F15: 14 | G15: 35.31034 | H15: -120.66298 | I15: W3HjVEeEFWXa94BMF8iP5lQOZU03 | J15: 1.0787876 | K15: iPhone13,3 | L15: 2.4.2 | M15: 2 | N15: 2 | O15: 1 | R15: TREE 2 QUAG | S15: W25 inventory | T15: coastal live oak | U15: https://firebasestorage.googleapis.com/v0/b/wt-foundation-production.appspot.com/o/measurements%2FMeasureMethod.ADM_FIXED_PCT%2FdbhPhoto%2F1773896233465?alt=media&token=033c44e3-86c4-420a-8514-869a443f380b | V15: https://firebasestorage.googleapis.com/v0/b/wt-foundation-production.appspot.com/o/measurements%2FMeasureMethod.ADM_FIXED_PCT%2FheightPhoto%2F1773896225606?alt=media&token=ef6e46b9-d5f6-4e6b-a1a1-64393b4e31f8 | W15: https://firebasestorage.googleapis.com/v0/b/wt-foundation-production.appspot.com/o/measurements%2FMeasureMethod.ADM_FIXED_PCT%2Fdepth%2F1773896235794?alt=media&token=a60fdfca-41f5-452e-8698-16730d3936c1 | X15: 0.2349537 | Y15: 1.5812417 | Z15: 0.36972548 | AA15: DmtEya4gP8UZf3xGjudN
A16: 2026_03_17 16:38:59 | B16: 0.29416447 | C16: ADM Fixed Percent | D16: 13.286857 | E16: 0.306 | F16: 12 | G16: 35.309637 | H16: -120.663 | I16: W3HjVEeEFWXa94BMF8iP5lQOZU03 | J16: 1.4106413 | K16: iPhone13,3 | L16: 2.4.2 | M16: 2 | N16: 3 | O16: 1 | R16: TREE 3 | S16: W25 inventory | T16: coastal live oak | U16: https://firebasestorage.googleapis.com/v0/b/wt-foundation-production.appspot.com/o/measurements%2FMeasureMethod.ADM_FIXED_PCT%2FdbhPhoto%2F1773896249194?alt=media&token=3b376066-4454-48fd-b892-faf0344af16f | V16: https://firebasestorage.googleapis.com/v0/b/wt-foundation-production.appspot.com/o/measurements%2FMeasureMethod.ADM_FIXED_PCT%2FheightPhoto%2F1773896238754?alt=media&token=8dbe8db8-4057-403c-b83f-e3ef7aa12c62 | W16: https://firebasestorage.googleapis.com/v0/b/wt-foundation-production.appspot.com/o/measurements%2FMeasureMethod.ADM_FIXED_PCT%2Fdepth%2F1773953842239?alt=media&token=69d8eee1-5916-43aa-af22-4ca6ac4106c2 | X16: 0.23697917 | Y16: 1.1265912 | Z16: 0.26374749 | AA16: 4LF6LKtvT98GEfDD5xMH
A17: 2026_03_17 16:42:37 | B17: 0.44833852 | C17: ADM Fixed Percent | D17: 15.918393 | E17: 0.472 | F17: 14.7 | G17: 35.310332 | H17: -120.6629 | I17: W3HjVEeEFWXa94BMF8iP5lQOZU03 | J17: 1.2671713 | K17: iPhone13,3 | L17: 2.4.2 | M17: 2 | N17: 4 | O17: 1 | R17: TREE 4 | S17: W25 inventory | T17: coastal live oak | U17: https://firebasestorage.googleapis.com/v0/b/wt-foundation-production.appspot.com/o/measurements%2FMeasureMethod.ADM_FIXED_PCT%2FdbhPhoto%2F1773897074510?alt=media&token=bb963d49-ea06-4d09-832a-84641283da42 | V17: https://firebasestorage.googleapis.com/v0/b/wt-foundation-production.appspot.com/o/measurements%2FMeasureMethod.ADM_FIXED_PCT%2FheightPhoto%2F1773953842243?alt=media&token=cbe864de-8f69-4a2b-8fc7-52afaaf7e1cf | W17: https://firebasestorage.googleapis.com/v0/b/wt-foundation-production.appspot.com/o/measurements%2FMeasureMethod.ADM_FIXED_PCT%2Fdepth%2F1773897074529?alt=media&token=951a3a58-a18e-46e9-a589-d56db3e6e7f9 | X17: 0.23177083 | Y17: 1.72259 | Z17: 0.4013399 | AA17: qJBGt7dSbjhSi7PfTBxa
A18: 2026_03_17 16:49:51 | B18: 0.50010013 | C18: ADM Fixed Percent | D18: 14.13728 | E18: 0.475 | F18: 14 | G18: 35.308929 | H18: -120.66026 | I18: W3HjVEeEFWXa94BMF8iP5lQOZU03 | J18: 1.0874438 | K18: iPhone13,3 | L18: 2.4.2 | M18: 2 | N18: 5 | O18: 1 | R18: TREE 5 | S18: W25 inventory | T18: coastal live oak | U18: https://firebasestorage.googleapis.com/v0/b/wt-foundation-production.appspot.com/o/measurements%2FMeasureMethod.ADM_FIXED_PCT%2FdbhPhoto%2F1773953875697?alt=media&token=75308296-1ce8-4a84-9ba8-895841dfac30 | V18: https://firebasestorage.googleapis.com/v0/b/wt-foundation-production.appspot.com/o/measurements%2FMeasureMethod.ADM_FIXED_PCT%2FheightPhoto%2F1773953856766?alt=media&token=ecb0ef64-b031-4aa1-aae9-578ee9dfcc02 | W18: https://firebasestorage.googleapis.com/v0/b/wt-foundation-production.appspot.com/o/measurements%2FMeasureMethod.ADM_FIXED_PCT%2Fdepth%2F1773898525775?alt=media&token=8323d491-3cb8-4a2a-af2b-6154805437bf | X18: 0.23181573 | Y18: 1.8809382 | Z18: 0.45066897 | AA18: nYjd8igCiq99IBULjWku
A19: 2026_03_17 17:03:42 | B19: 0.47424682 | C19: ADM Fixed Percent | D19: 12.353354 | E19: 0.514 | F19: 11.8 | G19: 35.309592 | H19: -120.66297 | I19: W3HjVEeEFWXa94BMF8iP5lQOZU03 | J19: 1.1837962 | K19: iPhone13,3 | L19: 2.4.2 | M19: 2 | N19: 6 | O19: 1 | R19: TREE 6 | S19: W25 inventory | T19: coastal live oak | U19: https://firebasestorage.googleapis.com/v0/b/wt-foundation-production.appspot.com/o/measurements%2FMeasureMethod.ADM_FIXED_PCT%2FdbhPhoto%2F1773953876675?alt=media&token=9c6987cf-b936-42d7-9658-830c7f9683f0 | V19: https://firebasestorage.googleapis.com/v0/b/wt-foundation-production.appspot.com/o/measurements%2FMeasureMethod.ADM_FIXED_PCT%2FheightPhoto%2F1773898779433?alt=media&token=448f0eac-2366-4952-9316-9e538a65cb5c | W19: https://firebasestorage.googleapis.com/v0/b/wt-foundation-production.appspot.com/o/measurements%2FMeasureMethod.ADM_FIXED_PCT%2Fdepth%2F1773899032925?alt=media&token=512ba16d-9a9d-4684-80fa-d04e07a820b8 | X19: 0.24972512 | Y19: 1.860444 | Z19: 0.42757585 | AA19: AqgBKUVtIQUV6psxy1ZK
A20: 2026_03_17 17:08:33 | B20: 0.2136557 | C20: ADM Fixed Percent | D20: 12.555085 | E20: 0.231 | F20: 10.9 | G20: 35.309358 | H20: -120.66195 | I20: W3HjVEeEFWXa94BMF8iP5lQOZU03 | J20: 1.1967772 | K20: iPhone13,3 | L20: 2.4.2 | M20: 2 | N20: 7 | O20: 1 | R20: TREE 7 | S20: W25 inventory | T20: coastal live oak | U20: https://firebasestorage.googleapis.com/v0/b/wt-foundation-production.appspot.com/o/measurements%2FMeasureMethod.ADM_FIXED_PCT%2FdbhPhoto%2F1773953887904?alt=media&token=47414445-6eaf-483a-94f4-51eff94748a7 | V20: https://firebasestorage.googleapis.com/v0/b/wt-foundation-production.appspot.com/o/measurements%2FMeasureMethod.ADM_FIXED_PCT%2FheightPhoto%2F1773953886200?alt=media&token=48130c94-da35-46ac-92ed-0544dc2fa4f7 | W20: https://firebasestorage.googleapis.com/v0/b/wt-foundation-production.appspot.com/o/measurements%2FMeasureMethod.ADM_FIXED_PCT%2Fdepth%2F1773953902602?alt=media&token=958e09c2-434c-4f54-b663-158a2835b2fe | X20: 0.23958333 | Y20: 0.82625908 | Z20: 0.19297959 | AA20: w2EflcNCJyzDMLkKGcZI
A21: 2026_03_17 17:11:31 | B21: 0.2840854 | C21: ADM Fixed Percent | D21: 11.706635 | E21: 0.3 | F21: 11 | G21: 35.309356 | H21: -120.66318 | I21: W3HjVEeEFWXa94BMF8iP5lQOZU03 | J21: 1.2723949 | K21: iPhone13,3 | L21: 2.4.2 | M21: 2 | N21: 8 | O21: 1 | R21: TREE 8 stem 1 | S21: W25 inventory | T21: coastal live oak | U21: https://firebasestorage.googleapis.com/v0/b/wt-foundation-production.appspot.com/o/measurements%2FMeasureMethod.ADM_FIXED_PCT%2FdbhPhoto%2F1773953943882?alt=media&token=8456f02d-4763-458a-9937-826bac91b1a0 | V21: https://firebasestorage.googleapis.com/v0/b/wt-foundation-production.appspot.com/o/measurements%2FMeasureMethod.ADM_FIXED_PCT%2FheightPhoto%2F1773953934056?alt=media&token=8e989daf-f34b-4f01-9d57-5f358e7ef08a | W21: https://firebasestorage.googleapis.com/v0/b/wt-foundation-production.appspot.com/o/measurements%2FMeasureMethod.ADM_FIXED_PCT%2Fdepth%2F1773953982390?alt=media&token=8d725adb-1c0e-4315-a62a-0b384c1b7872 | X21: 0.24441964 | Y21: 1.0959784 | Z21: 0.25664469 | AA21: 652raVd2kbK0ZeJmOAVW
A22: 2026_03_17 17:13:31 | B22: 0.11520453 | C22: ADM Fixed Percent | D22: 1.2167292 | E22: 0.125 | F22: 1.3 | G22: 35.30889 | H22: -120.66042 | I22: W3HjVEeEFWXa94BMF8iP5lQOZU03 | J22: 1.2541616 | K22: iPhone13,3 | L22: 2.4.2 | M22: 2 | N22: 8 | O22: 2 | R22: TREE 8 Stem 2 | S22: W25 inventory | T22: coastal live oak | U22: https://firebasestorage.googleapis.com/v0/b/wt-foundation-production.appspot.com/o/measurements%2FMeasureMethod.ADM_FIXED_PCT%2FdbhPhoto%2F1773953998239?alt=media&token=5d7fee51-52d0-4cc6-aeb3-35b75d658442 | V22: https://firebasestorage.googleapis.com/v0/b/wt-foundation-production.appspot.com/o/measurements%2FMeasureMethod.ADM_FIXED_PCT%2FheightPhoto%2F1773953995740?alt=media&token=2ce58c79-02fa-4fe3-8034-665ffbd15b81 | W22: https://firebasestorage.googleapis.com/v0/b/wt-foundation-production.appspot.com/o/measurements%2FMeasureMethod.ADM_FIXED_PCT%2Fdepth%2F1773954006167?alt=media&token=98b7cac1-23f8-4b1c-bb87-8cdb1bc25415 | X22: 0.24739583 | Y22: 0.4507046 | Z22: 0.10419268 | AA22: orVvAINZtGIBGyh5jJL4
A23: 2026_03_17 17:14:48 | B23: 0.10228355 | C23: ADM Fixed Percent | D23: 1.1859745 | E23: 0.11 | F23: 1.3 | G23: 35.309432 | H23: -120.66231 | I23: W3HjVEeEFWXa94BMF8iP5lQOZU03 | J23: 1.1839586 | K23: iPhone13,3 | L23: 2.4.2 | M23: 2 | N23: 8 | O23: 3 | R23: TREE 8 stem 3 | S23: W25 inventory | T23: coastal live oak | U23: https://firebasestorage.googleapis.com/v0/b/wt-foundation-production.appspot.com/o/measurements%2FMeasureMethod.ADM_FIXED_PCT%2FdbhPhoto%2F1773923493480?alt=media&token=2a778542-6844-4c13-9fea-455326766e52 | V23: https://firebasestorage.googleapis.com/v0/b/wt-foundation-production.appspot.com/o/measurements%2FMeasureMethod.ADM_FIXED_PCT%2FheightPhoto%2F1773923493493?alt=media&token=17f963fb-0ecb-4f57-82a9-5b335c9f5dc6 | W23: https://firebasestorage.googleapis.com/v0/b/wt-foundation-production.appspot.com/o/measurements%2FMeasureMethod.ADM_FIXED_PCT%2Fdepth%2F1773923561968?alt=media&token=b55f1422-112b-498e-8d2a-5e7353f289f8 | X23: 0.23809524 | Y23: 0.38979264 | Z23: 0.092188685 | AA23: V8H3SD1JVmdziwZbJKkT
A24: 2026_03_17 17:20:12 | B24: 0.28040143 | C24: ADM Fixed Percent | D24: 10.255904 | E24: 0.338 | F24: 10 | G24: 35.310365 | H24: -120.66243 | I24: W3HjVEeEFWXa94BMF8iP5lQOZU03 | J24: 1.3200376 | K24: iPhone13,3 | L24: 2.4.2 | M24: 2 | N24: 9 | O24: 1 | R24: TREE 9 stem 1 | S24: W25 inventory | T24: coastal live oak | U24: https://firebasestorage.googleapis.com/v0/b/wt-foundation-production.appspot.com/o/measurements%2FMeasureMethod.ADM_FIXED_PCT%2FdbhPhoto%2F1773923579898?alt=media&token=94d178b1-7ae5-44e2-b9aa-d685a67d1250 | V24: https://firebasestorage.googleapis.com/v0/b/wt-foundation-production.appspot.com/o/measurements%2FMeasureMethod.ADM_FIXED_PCT%2FheightPhoto%2F1773923569048?alt=media&token=b7e4e035-e88b-408f-827a-6b871b9ac069 | W24: https://firebasestorage.googleapis.com/v0/b/wt-foundation-production.appspot.com/o/measurements%2FMeasureMethod.ADM_FIXED_PCT%2Fdepth%2F1773923710694?alt=media&token=53a9f0f8-9d78-4ce0-84f5-1c5389c069ba | X24: 0.24328807 | Y24: 1.1136653 | Z24: 0.253036 | AA24: sFULndRR9MSGTibfe9kg
A25: 2026_03_17 17:21:45 | B25: 0.18495096 | C25: ADM Fixed Percent | D25: 1.2358043 | E25: 0.213 | F25: 1.3 | G25: 35.309552 | H25: -120.66296 | I25: W3HjVEeEFWXa94BMF8iP5lQOZU03 | J25: 1.2390695 | K25: iPhone13,3 | L25: 2.4.2 | M25: 2 | N25: 9 | O25: 2 | R25: TREE 9 stem 2 | S25: W25 inventory | T25: coastal live oak | U25: https://firebasestorage.googleapis.com/v0/b/wt-foundation-production.appspot.com/o/measurements%2FMeasureMethod.ADM_FIXED_PCT%2FdbhPhoto%2F1773954020462?alt=media&token=5bd22f61-0bc4-4ff8-82cf-dae70da4cc83 | V25: https://firebasestorage.googleapis.com/v0/b/wt-foundation-production.appspot.com/o/measurements%2FMeasureMethod.ADM_FIXED_PCT%2FheightPhoto%2F1773954019557?alt=media&token=243bd838-d08f-499f-b70e-853422d2f445 | W25: https://firebasestorage.googleapis.com/v0/b/wt-foundation-production.appspot.com/o/measurements%2FMeasureMethod.ADM_FIXED_PCT%2Fdepth%2F1773954028109?alt=media&token=8f516ead-c1a2-49d1-967c-0fd81f560249 | X25: 0.25390625 | Y25: 0.7027728 | Z25: 0.16617223 | AA25: L3j13lTaJLyKLjzaltso
... A94: 2026_03_18 18:30:47 | B94: 0.099652278 | C94: ADM Fixed Percent | D94: 5.5528312 | E94: 0.226 | F94: 5.8 | G94: 35.309575 | H94: -120.66291 | I94: W3HjVEeEFWXa94BMF8iP5lQOZU03 | J94: 1.1061445 | K94: iPhone13,3 | L94: 2.4.3 | M94: 8 | N94: 1 | O94: 1 | R94: TREE 1 potentially come back to (many many stems) DAY 2 | S94: W25 inventory | T94: monterey cypress | U94: https://firebasestorage.googleapis.com/v0/b/wt-foundation-production.appspot.com/o/measurements%2FMeasureMethod.ADM_FIXED_PCT%2FdbhPhoto%2F1773952211729?alt=media&token=90654eeb-5ad9-45f3-919a-a5541e6a96c2 | V94: https://firebasestorage.googleapis.com/v0/b/wt-foundation-production.appspot.com/o/measurements%2FMeasureMethod.ADM_FIXED_PCT%2FheightPhoto%2F1773952200994?alt=media&token=7e974e7b-28c5-4c7b-8dce-cc9c89babd9b | W94: https://firebasestorage.googleapis.com/v0/b/wt-foundation-production.appspot.com/o/measurements%2FMeasureMethod.ADM_FIXED_PCT%2Fdepth%2F1773952219384?alt=media&token=4db5c223-956c-40e4-99df-4b971605d272 | X94: 0.29340278 | Y94: 0.73376703 | Z94: 0.096141632 | AA94: nyJGdAiipk8a7XIWMCTB
A95: 2026_03_18 18:38:51 | B95: 0.0985445 | C95: ADM Fixed Percent | D95: 6.8587747 | E95: 0.122 | F95: 5.9 | G95: 35.309627 | H95: -120.66294 | I95: W3HjVEeEFWXa94BMF8iP5lQOZU03 | J95: 2.0944996 | K95: iPhone13,3 | L95: 2.4.3 | M95: x | N95: 1 | O95: 1 | R95: TREE 1 stem 1 DAY 2 | S95: W25 inventory | T95: unknown | U95: https://firebasestorage.googleapis.com/v0/b/wt-foundation-production.appspot.com/o/measurements%2FMeasureMethod.ADM_FIXED_PCT%2FdbhPhoto%2F1773952473085?alt=media&token=eb6bf63b-85fa-40c9-8e83-889ff862b141 | V95: https://firebasestorage.googleapis.com/v0/b/wt-foundation-production.appspot.com/o/measurements%2FMeasureMethod.ADM_FIXED_PCT%2FheightPhoto%2F1773952465403?alt=media&token=ca1bd186-3ee1-4a38-a2a5-c15445f76c98 | W95: https://firebasestorage.googleapis.com/v0/b/wt-foundation-production.appspot.com/o/measurements%2FMeasureMethod.ADM_FIXED_PCT%2Fdepth%2F1773952479821?alt=media&token=c0b912c3-33c5-4c0b-b9de-ba716443426d | X95: 0.25520833 | Y95: 0.38543811 | Z95: 0.089065134 | AA95: F6I4UpH06gcWb6F7XLtN
A96: 2026_03_18 18:43:04 | B96: 0.034890233 | C96: ADM Fixed Percent | D96: 0.63281035 | E96: 0.035 | F96: 1.3 | G96: 35.3096 | H96: -120.66295 | I96: W3HjVEeEFWXa94BMF8iP5lQOZU03 | J96: 1.1677366 | K96: iPhone13,3 | L96: 2.4.3 | M96: x | N96: 1 | O96: 2 | R96: TREE 1 stem 2 DAY 2 | S96: W25 inventory | T96: unknown | U96: https://firebasestorage.googleapis.com/v0/b/wt-foundation-production.appspot.com/o/measurements%2FMeasureMethod.ADM_FIXED_PCT%2FdbhPhoto%2F1773952509900?alt=media&token=8e42552e-547d-41d0-9ff0-cd45fe445801 | V96: https://firebasestorage.googleapis.com/v0/b/wt-foundation-production.appspot.com/o/measurements%2FMeasureMethod.ADM_FIXED_PCT%2FheightPhoto%2F1773952496828?alt=media&token=f8539f8a-cb36-4b79-8e27-b8ebb7aa8bf8 | W96: https://firebasestorage.googleapis.com/v0/b/wt-foundation-production.appspot.com/o/measurements%2FMeasureMethod.ADM_FIXED_PCT%2Fdepth%2F1773952600417?alt=media&token=3a71ece7-fc82-4319-bd8d-ffeeb66acad1 | X96: 0.21316964 | Y96: 1.951871 | Z96: 0.026191648 | AA96: ZJL2NEsCPv8BTqhUztck
A97: 2026_03_18 18:52:00 | B97: 0.046117154 | C97: ADM Fixed Percent | D97: 1.5676272 | E97: 0.053 | F97: 1.3 | G97: 35.309591 | H97: -120.66295 | I97: W3HjVEeEFWXa94BMF8iP5lQOZU03 | J97: 4.1538639 | K97: iPhone13,3 | L97: 2.4.3 | M97: x | N97: 1 | O97: 3 | R97: TREE 1 stem 3 DAY 2 | S97: W25 inventory | T97: unknown | U97: https://firebasestorage.googleapis.com/v0/b/wt-foundation-production.appspot.com/o/measurements%2FMeasureMethod.ADM_FIXED_PCT%2FdbhPhoto%2F1773952629994?alt=media&token=8a62a751-b820-4975-b104-97bd0192bc46 | V97: https://firebasestorage.googleapis.com/v0/b/wt-foundation-production.appspot.com/o/measurements%2FMeasureMethod.ADM_FIXED_PCT%2FheightPhoto%2F1773952611320?alt=media&token=12405104-e7af-4b2a-9aca-16ba2d44b488 | W97: https://firebasestorage.googleapis.com/v0/b/wt-foundation-production.appspot.com/o/measurements%2FMeasureMethod.ADM_FIXED_PCT%2Fdepth%2F1773952869528?alt=media&token=b9f01141-dfe5-45b5-8162-29e0485ba2fd | X97: 0.22463768 | Y97: 1.4727821 | Z97: 0.05011664 | AA97: RcybfURdMDPhHqXn5pT1
A98: 2026_03_18 18:53:25 | B98: 0.060299719 | C98: ADM Fixed Percent | D98: 1.6852882 | E98: 0.055 | F98: 1.3 | G98: 35.309617 | H98: -120.66295 | I98: W3HjVEeEFWXa94BMF8iP5lQOZU03 | J98: 6.900919 | K98: iPhone13,3 | L98: 2.4.3 | M98: x | N98: 1 | O98: 4 | R98: TREE 1 stem 4 DAY 2 | S98: W25 inventory | T98: unknown | U98: https://firebasestorage.googleapis.com/v0/b/wt-foundation-production.appspot.com/o/measurements%2FMeasureMethod.ADM_FIXED_PCT%2FdbhPhoto%2F1773952995712?alt=media&token=45b1dd9c-9263-49af-8973-798711807d4c | V98: https://firebasestorage.googleapis.com/v0/b/wt-foundation-production.appspot.com/o/measurements%2FMeasureMethod.ADM_FIXED_PCT%2FheightPhoto%2F1773952872570?alt=media&token=86ebc59c-96bc-4165-b608-10d016dc6ee8 | W98: https://firebasestorage.googleapis.com/v0/b/wt-foundation-production.appspot.com/o/measurements%2FMeasureMethod.ADM_FIXED_PCT%2Fdepth%2F1773953002322?alt=media&token=e13bcafc-047f-425d-ac69-ccdc05ac804d | X98: 0.21417969 | Y98: 0.24994047 | Z98: 0.054295384 | AA98: QByKHAaVN9NMP3LDruCw
A99: 2026_03_18 18:55:02 | B99: 0.08157548 | C99: ADM Fixed Percent | D99: 24.651197 | E99: 0.097 | F99: 1.3 | G99: 35.309613 | H99: -120.66294 | I99: W3HjVEeEFWXa94BMF8iP5lQOZU03 | J99: 3.0387106 | K99: iPhone13,3 | L99: 2.4.3 | M99: x | N99: 1 | O99: 5 | R99: TREE 1 stem 5 DAY 2 | S99: W25 inventory | T99: unknown | U99: https://firebasestorage.googleapis.com/v0/b/wt-foundation-production.appspot.com/o/measurements%2FMeasureMethod.ADM_FIXED_PCT%2FdbhPhoto%2F1773953015288?alt=media&token=66d8bdec-92bb-426b-842f-084203530779 | V99: https://firebasestorage.googleapis.com/v0/b/wt-foundation-production.appspot.com/o/measurements%2FMeasureMethod.ADM_FIXED_PCT%2FheightPhoto%2F1773953010352?alt=media&token=d4e00bcb-1069-4b64-bad1-ec36d192a9cb | W99: https://firebasestorage.googleapis.com/v0/b/wt-foundation-production.appspot.com/o/measurements%2FMeasureMethod.ADM_FIXED_PCT%2Fdepth%2F1773953035173?alt=media&token=d4d67e2a-9e3d-46c8-b792-9d5b3defdb87 | X99: 0.22760417 | Y99: 0.32293394 | Z99: 0.073957067 | AA99: bOkCTV0shyAfisr3Z6Wh
A100: 2026_04_17 18:29:10 | B100: 0.43707663 | C100: ADM Fixed Percent | D100: 19.983576 | E100: 0.453 | F100: 18.7 | G100: 35.310456 | H100: -120.66259 | I100: GNNIaIPthVQKUTVjjbAekjaxeHo1 | K100: iPhone13,3 | L100: 2.5.0 | P100: west calif garden trees | R100: 1.1 | S100: W25 inventory | T100: white alder | U100: https://firebasestorage.googleapis.com/v0/b/wt-foundation-production.appspot.com/o/measurements%2FMeasureMethod.ADM_FIXED_PCT%2FdbhPhoto%2F1776452670497?alt=media&token=b28a4cc8-bf52-4e9a-952c-eff292dcc2ae | V100: https://firebasestorage.googleapis.com/v0/b/wt-foundation-production.appspot.com/o/measurements%2FMeasureMethod.ADM_FIXED_PCT%2FheightPhoto%2F1776452670497?alt=media&token=c9306caa-b2ad-4701-9af1-84e9c44013e1 | AA100: groAZcbdS84uNAoNZlcO
A101: 2026_04_17 18:32:54 | B101: 0.84838415 | C101: ADM Fixed Percent | D101: 23.091753 | E101: 0.843 | F101: 22.3 | G101: 35.310358 | H101: -120.66251 | I101: GNNIaIPthVQKUTVjjbAekjaxeHo1 | K101: iPhone13,3 | L101: 2.5.0 | M101: 1 | N101: 12 | O101: 1 | P101: west calif garden trees | R101: 2.1.1 redwood tree 1, already did tree 2 | S101: W25 inventory | T101: coast redwood | U101: https://firebasestorage.googleapis.com/v0/b/wt-foundation-production.appspot.com/o/measurements%2FMeasureMethod.ADM_FIXED_PCT%2FdbhPhoto%2F1776452681598?alt=media&token=9465de9a-d95b-4f0b-90be-12aad87167cb | V101: https://firebasestorage.googleapis.com/v0/b/wt-foundation-production.appspot.com/o/measurements%2FMeasureMethod.ADM_FIXED_PCT%2FheightPhoto%2F1776452670497?alt=media&token=c9306caa-b2ad-4701-9af1-84e9c44013e1 | AA101: nxd2Q6jcYUigv1dygWyU
A102: 2026_04_17 18:40:10 | B102: 0.085372111 | C102: ADM Fixed Percent | D102: 5.9517384 | E102: 0.094 | F102: 6 | G102: 35.310505 | H102: -120.66245 | I102: GNNIaIPthVQKUTVjjbAekjaxeHo1 | K102: iPhone13,3 | L102: 2.5.0 | M102: 1 | N102: 6 | O102: 1 | P102: west calif garden trees | R102: tree 6 (skinny tree) | S102: W25 inventory | T102: coast redwood | U102: https://firebasestorage.googleapis.com/v0/b/wt-foundation-production.appspot.com/o/measurements%2FMeasureMethod.ADM_FIXED_PCT%2FdbhPhoto%2F1776452682787?alt=media&token=c19543db-557f-4be7-bed0-e7ab3903d2c9 | V102: https://firebasestorage.googleapis.com/v0/b/wt-foundation-production.appspot.com/o/measurements%2FMeasureMethod.ADM_FIXED_PCT%2FheightPhoto%2F1776452681789?alt=media&token=477d8e53-dcf8-4660-b637-60415216e953 | AA102: IG075HUxpUV7QcykiQoZ
A103: 2026_04_17 18:45:56 | B103: 0.11369289 | C103: ADM Fixed Percent | D103: 8.9318419 | G103: 35.310513 | H103: -120.66242 | I103: GNNIaIPthVQKUTVjjbAekjaxeHo1 | K103: iPhone13,3 | L103: 2.5.0 | M103: 1 | N103: 13 | O103: 1 | P103: west calif garden trees | S103: W25 inventory | T103: coast redwood | U103: https://firebasestorage.googleapis.com/v0/b/wt-foundation-production.appspot.com/o/measurements%2FMeasureMethod.ADM_FIXED_PCT%2FdbhPhoto%2F1776452686472?alt=media&token=3d95a966-31f5-40da-97dd-6a10592f5e2c | V103: https://firebasestorage.googleapis.com/v0/b/wt-foundation-production.appspot.com/o/measurements%2FMeasureMethod.ADM_FIXED_PCT%2FheightPhoto%2F1776452683885?alt=media&token=7e8e45cd-6662-4569-8f97-27791d6fc428 | AA103: mBE02a34GnZYTHnQGfIz
A104: 2026_04_17 18:48:40 | B104: 0.13882809 | C104: ADM Fixed Percent | D104: 8.4683819 | G104: 35.310528 | H104: -120.66239 | I104: GNNIaIPthVQKUTVjjbAekjaxeHo1 | K104: iPhone13,3 | L104: 2.5.0 | M104: 1 | N104: 14 | O104: 1 | P104: west calif garden trees | S104: W25 inventory | T104: coast redwood | U104: https://firebasestorage.googleapis.com/v0/b/wt-foundation-production.appspot.com/o/measurements%2FMeasureMethod.ADM_FIXED_PCT%2FdbhPhoto%2F1776654422410?alt=media&token=5e2f48bb-4795-4c8a-8dd6-d989cd15a90f | V104: https://firebasestorage.googleapis.com/v0/b/wt-foundation-production.appspot.com/o/measurements%2FMeasureMethod.ADM_FIXED_PCT%2FheightPhoto%2F1776654422409?alt=media&token=609d9647-feba-4b7b-9375-0272354f21dd | AA104: 1HbatzL5Fa1i5zoRCJH5
A105: 2026_04_17 19:08:07 | B105: 0.11790149 | C105: ADM Fixed Percent | D105: 6.8544779 | E105: 0.135 | F105: 6.7 | G105: 35.310301 | H105: -120.66258 | I105: GNNIaIPthVQKUTVjjbAekjaxeHo1 | K105: iPhone13,3 | L105: 2.5.0 | M105: 9 | N105: 1 | O105: 1 | P105: west calif garden trees | R105: tree1, strem1 | S105: W25 inventory | T105: buckeye | U105: https://firebasestorage.googleapis.com/v0/b/wt-foundation-production.appspot.com/o/measurements%2FMeasureMethod.ADM_FIXED_PCT%2FdbhPhoto%2F1776654425185?alt=media&token=4cebad13-1774-4053-b4f5-3b6adc7555f1 | V105: https://firebasestorage.googleapis.com/v0/b/wt-foundation-production.appspot.com/o/measurements%2FMeasureMethod.ADM_FIXED_PCT%2FheightPhoto%2F1776654422410?alt=media&token=20bf94ae-2773-4582-bafb-549d2a7e3cd4 | AA105: IxXgDuzBYdz7nI5gzs71
A106: 2026_04_17 19:09:50 | B106: 0.13842589 | C106: ADM Fixed Percent | D106: 1.3332841 | E106: 0.189 | F106: 1.3 | G106: 35.310319 | H106: -120.66263 | I106: GNNIaIPthVQKUTVjjbAekjaxeHo1 | K106: iPhone13,3 | L106: 2.5.0 | M106: 9 | N106: 1 | O106: 2 | P106: west calif garden trees | R106: b tree 1 stem 2 | S106: W25 inventory | T106: buckeye | U106: https://firebasestorage.googleapis.com/v0/b/wt-foundation-production.appspot.com/o/measurements%2FMeasureMethod.ADM_FIXED_PCT%2FdbhPhoto%2F1776654430786?alt=media&token=2d8a476e-0aec-460a-8a60-af3e90588345 | V106: https://firebasestorage.googleapis.com/v0/b/wt-foundation-production.appspot.com/o/measurements%2FMeasureMethod.ADM_FIXED_PCT%2FheightPhoto%2F1776654428599?alt=media&token=af145197-5416-4836-be26-9056db12d394 | AA106: PBG6MYS94yeieTV5sPB2
A107: 2026_04_17 19:11:40 | B107: 0.10576433 | C107: ADM Fixed Percent | D107: 1.4054316 | E107: 0.121 | F107: 1.3 | G107: 35.310322 | H107: -120.66261 | I107: GNNIaIPthVQKUTVjjbAekjaxeHo1 | K107: iPhone13,3 | L107: 2.5.0 | M107: 9 | N107: 1 | O107: 3 | P107: west calif garden trees | R107: 1.3 | S107: W25 inventory | T107: buckeye | U107: https://firebasestorage.googleapis.com/v0/b/wt-foundation-production.appspot.com/o/measurements%2FMeasureMethod.ADM_FIXED_PCT%2FdbhPhoto%2F1776654434245?alt=media&token=17577fe1-f5d1-4081-aa9f-df1ecac58433 | V107: https://firebasestorage.googleapis.com/v0/b/wt-foundation-production.appspot.com/o/measurements%2FMeasureMethod.ADM_FIXED_PCT%2FheightPhoto%2F1776654433514?alt=media&token=92f116b7-10d7-4bb2-a623-d9800064135b | AA107: HUHyCQJskxSEnEDToAJD
A108: 2026_04_17 19:13:04 | B108: 0.10219656 | C108: ADM Fixed Percent | D108: 1.3178774 | E108: 0.113 | F108: 1.3 | G108: 35.310327 | H108: -120.66261 | I108: GNNIaIPthVQKUTVjjbAekjaxeHo1 | K108: iPhone13,3 | L108: 2.5.0 | M108: 9 | N108: 1 | O108: 4 | P108: west calif garden trees | R108: 1.4 | S108: W25 inventory | T108: buckeye | U108: https://firebasestorage.googleapis.com/v0/b/wt-foundation-production.appspot.com/o/measurements%2FMeasureMethod.ADM_FIXED_PCT%2FdbhPhoto%2F1776654440742?alt=media&token=457a3e6c-1e4e-4c92-9066-4606402251d6 | V108: https://firebasestorage.googleapis.com/v0/b/wt-foundation-production.appspot.com/o/measurements%2FMeasureMethod.ADM_FIXED_PCT%2FheightPhoto%2F1776654438445?alt=media&token=90c7d29b-ec1e-462d-a93f-07830e7b82d1 | AA108: MxeBgluxCBTbr1SmCLKT
...

Sheet Footprint Trees
A1: Date | B1: DBH (m) | C1: method | D1: Height (m) | E1: GT DBH (m) | F1: GT Height (m) | G1: WT_latitude | H1: WT_longitude | I1: Lat | J1: Long | K1: user_id | L1: DBH Height (m) | M1: phone_model | N1: app_version | O1: Species # | P1: Species | Q1: Tree # | R1: Stem # | S1: Footprint | T1: GPS? | U1: Edits? | V1: notes | W1: project | X1: Species - Common Name | Y1: Species - Scientific Name | Z1: dbh_photo_url | AA1: height_photo_url | AB1: dmap_zip_url | AC1: trunk_occupancy | AD1: trunk_dist_m | AE1: apparent_dbh_med_m | AF1: measurement_id | AI1: Field Maps Image Link
A2: 2026_05_01 18:48:10 | B2: 0.13004179 | C2: ADM Fixed Percent | D2: 9.8815746 | E2: 0.161 | F2: 10.8 | G2: 35.310824 | H2: -120.66286 | I2: 35.310844 | J2: -120.66284 | K2: GNNIaIPthVQKUTVjjbAekjaxeHo1 | M2: iPhone13,3 | N2: 2.5.0 | O2: 10 | P2: 1 | Q2: 1 | R2: 1 | S2: 1 | T2: y | V2: tree2 stem 1 | W2: W25 inventory | X2: weeping bottlebrush | Y2: Callistemon viminalis | Z2: https://firebasestorage.googleapis.com/v0/b/wt-foundation-production.appspot.com/o/measurements%2FMeasureMethod.ADM_FIXED_PCT%2FdbhPhoto%2F1777661297248?alt=media&token=526bd46a-f805-431a-b911-8a142a70c727 | AA2: https://firebasestorage.googleapis.com/v0/b/wt-foundation-production.appspot.com/o/measurements%2FMeasureMethod.ADM_FIXED_PCT%2FheightPhoto%2F1777661290457?alt=media&token=b4ebca95-2e65-43df-8ef5-eb5dcdb53827 | AF2: QOjHNpx34kv12ntZNUYx
A3: 2026_05_01 18:49:41 | B3: 0.11198821 | C3: {=SQRT(SUMPRODUCT((($P$2:$P$1036='Footprint Trees'!Q:QV2)*($Q$2:$Q$1036=W2))*($B$2:$B$1036)^2))} -> #NAME? | D3: 1.2933545 | E3: 0.122 | F3: 1.3 | G3: 35.310829 | H3: -120.66289 | K3: GNNIaIPthVQKUTVjjbAekjaxeHo1 | M3: iPhone13,3 | N3: 2.5.0 | O3: 10 | P3: 1 | Q3: 1 | R3: 2 | S3: 1 | V3: tree 2 stem 2 | W3: W25 inventory | X3: weeping bottlebrush | Y3: Callistemon viminalis | Z3: https://firebasestorage.googleapis.com/v0/b/wt-foundation-production.appspot.com/o/measurements%2FMeasureMethod.ADM_FIXED_PCT%2FdbhPhoto%2F1777661391152?alt=media&token=c3558e55-ff89-4fc8-99f9-ca71d0556998 | AA3: https://firebasestorage.googleapis.com/v0/b/wt-foundation-production.appspot.com/o/measurements%2FMeasureMethod.ADM_FIXED_PCT%2FheightPhoto%2F1777661381410?alt=media&token=3c847b7a-5858-40ac-8325-728586e68bfa | AF3: 59ib3pLODPtZI653mZoz
A4: 2026_05_01 18:54:05 | B4: 0.052926416 | C4: ADM Fixed Percent | D4: 1.292734 | E4: 0.057 | F4: 1.3 | G4: 35.310811 | H4: -120.6629 | K4: GNNIaIPthVQKUTVjjbAekjaxeHo1 | M4: iPhone13,3 | N4: 2.5.0 | O4: 10 | P4: 1 | Q4: 1 | R4: 3 | S4: 1 | V4: tree 2 stem 3 | W4: W25 inventory | X4: weeping bottlebrush | Y4: Callistemon viminalis | Z4: https://firebasestorage.googleapis.com/v0/b/wt-foundation-production.appspot.com/o/measurements%2FMeasureMethod.ADM_FIXED_PCT%2FdbhPhoto%2F1777661653256?alt=media&token=bb016a6c-3490-4cc7-a93e-2a70ef62a37b | AA4: https://firebasestorage.googleapis.com/v0/b/wt-foundation-production.appspot.com/o/measurements%2FMeasureMethod.ADM_FIXED_PCT%2FheightPhoto%2F1777661646197?alt=media&token=bd5bcb27-1762-4854-b594-a99d1e9fc935 | AF4: SFVjfO9QsYxMhghJzfc3
A5: 2026_05_01 18:56:21 | B5: 0.099103543 | C5: ADM Fixed Percent | D5: 1.2329431 | E5: 0.112 | F5: 1.3 | G5: 35.310846 | H5: -120.66289 | K5: GNNIaIPthVQKUTVjjbAekjaxeHo1 | M5: iPhone13,3 | N5: 2.5.0 | O5: 10 | P5: 1 | Q5: 1 | R5: 4 | S5: 1 | V5: tree 2 stem 4 | W5: W25 inventory | X5: weeping bottlebrush | Y5: Callistemon viminalis | Z5: https://firebasestorage.googleapis.com/v0/b/wt-foundation-production.appspot.com/o/measurements%2FMeasureMethod.ADM_FIXED_PCT%2FdbhPhoto%2F1777661793021?alt=media&token=14ef2caf-d682-4d95-bd8e-0e4ee67c3ef2 | AA5: https://firebasestorage.googleapis.com/v0/b/wt-foundation-production.appspot.com/o/measurements%2FMeasureMethod.ADM_FIXED_PCT%2FheightPhoto%2F1777661782039?alt=media&token=84b9beca-7199-485b-a109-46aac9087233 | AF5: mPYcbwO6DF607ObDNPML
A6: 2026_05_01 18:57:34 | B6: 0.095790288 | C6: ADM Fixed Percent | D6: 0.92759711 | E6: 0.109 | F6: 1.3 | G6: 35.310876 | H6: -120.66294 | K6: GNNIaIPthVQKUTVjjbAekjaxeHo1 | M6: iPhone13,3 | N6: 2.5.0 | O6: 10 | P6: 1 | Q6: 1 | R6: 5 | S6: 1 | V6: tree 2 stem5 | W6: W25 inventory | X6: weeping bottlebrush | Y6: Callistemon viminalis | Z6: https://firebasestorage.googleapis.com/v0/b/wt-foundation-production.appspot.com/o/measurements%2FMeasureMethod.ADM_FIXED_PCT%2FdbhPhoto%2F1777661861627?alt=media&token=99a05685-049d-4ad5-afad-0f198820a8f5 | AA6: https://firebasestorage.googleapis.com/v0/b/wt-foundation-production.appspot.com/o/measurements%2FMeasureMethod.ADM_FIXED_PCT%2FheightPhoto%2F1777661854488?alt=media&token=89cd7e5b-a286-437c-b48c-9b26ac25bb2b | AF6: hsqq3cPqmvEgE4pbhyDQ
A7: 2026_05_01 18:59:57 | B7: 0.084025712 | C7: ADM Fixed Percent | D7: 1.1133282 | E7: 0.088 | F7: 1.3 | G7: 35.310847 | H7: -120.66281 | K7: GNNIaIPthVQKUTVjjbAekjaxeHo1 | M7: iPhone13,3 | N7: 2.5.0 | O7: 10 | P7: 1 | Q7: 1 | R7: 6 | S7: 1 | V7: tree 2 stem 6 | W7: W25 inventory | X7: weeping bottlebrush | Y7: Callistemon viminalis | Z7: https://firebasestorage.googleapis.com/v0/b/wt-foundation-production.appspot.com/o/measurements%2FMeasureMethod.ADM_FIXED_PCT%2FdbhPhoto%2F1777662011072?alt=media&token=006cee0b-f419-4857-82bb-34fb5adb4aa6 | AA7: https://firebasestorage.googleapis.com/v0/b/wt-foundation-production.appspot.com/o/measurements%2FMeasureMethod.ADM_FIXED_PCT%2FheightPhoto%2F1777661998171?alt=media&token=ca3d5ddf-152b-4dfd-ac10-a7a05c1d08ee | AF7: pQlIvRwi8ADn8dW2lRon
A8: 2026_05_01 19:01:28 | B8: 0.10295464 | C8: ADM Fixed Percent | D8: 1.1891085 | E8: 0.105 | F8: 1.3 | G8: 35.31087 | H8: -120.66283 | K8: GNNIaIPthVQKUTVjjbAekjaxeHo1 | M8: iPhone13,3 | N8: 2.5.0 | O8: 10 | P8: 1 | Q8: 1 | R8: 7 | S8: 1 | V8: tree 2 stem 7 | W8: W25 inventory | X8: weeping bottlebrush | Y8: Callistemon viminalis | Z8: https://firebasestorage.googleapis.com/v0/b/wt-foundation-production.appspot.com/o/measurements%2FMeasureMethod.ADM_FIXED_PCT%2FdbhPhoto%2F1777662095644?alt=media&token=a17d7455-01ef-4f3d-a054-ef4b36f8eac5 | AA8: https://firebasestorage.googleapis.com/v0/b/wt-foundation-production.appspot.com/o/measurements%2FMeasureMethod.ADM_FIXED_PCT%2FheightPhoto%2F1777662088609?alt=media&token=0ba8bbdb-1454-4a6a-bc37-87701de0d5eb | AF8: 45m7RkG5D8ddtTfCiz3m
A9: 2026_05_01 19:07:30 | B9: 0.17142462 | C9: ADM Fixed Percent | D9: 10.652451 | E9: 0.167 | F9: 10 | G9: 35.310863 | H9: -120.66291 | I9: 35.310888 | J9: -120.66284 | K9: GNNIaIPthVQKUTVjjbAekjaxeHo1 | M9: iPhone13,3 | N9: 2.5.0 | O9: 11 | P9: 2 | Q9: 1 | R9: 1 | S9: 1 | T9: y | V9: tree3 | W9: W25 inventory | X9: punk tree / broad-leafed paperbark | Y9: Melaleuca quinquenervia | Z9: https://firebasestorage.googleapis.com/v0/b/wt-foundation-production.appspot.com/o/measurements%2FMeasureMethod.ADM_FIXED_PCT%2FdbhPhoto%2F1777662461728?alt=media&token=f97f008d-a028-486d-8b03-aee3483d2f3d | AA9: https://firebasestorage.googleapis.com/v0/b/wt-foundation-production.appspot.com/o/measurements%2FMeasureMethod.ADM_FIXED_PCT%2FheightPhoto%2F1777662451138?alt=media&token=2aeaef18-fc62-4515-9cbf-2d3fe497067a | AF9: t1APWlbm0fOrwao3cGuo
A10: 2026_05_01 19:14:01 | B10: 0.3206558 | C10: ADM Fixed Percent | D10: 13.21403 | E10: 0.328 | F10: 13.7 | G10: 35.310843 | H10: -120.66281 | I10: 35.310843 | J10: -120.66281 | K10: GNNIaIPthVQKUTVjjbAekjaxeHo1 | M10: iPhone13,3 | N10: 2.5.0 | O10: 11 | P10: 2 | Q10: 2 | R10: 1 | S10: 1 | T10: y | V10: tree4 | W10: W25 inventory | X10: punk tree / broad-leafed paperbark | Y10: Melaleuca quinquenervia | Z10: https://firebasestorage.googleapis.com/v0/b/wt-foundation-production.appspot.com/o/measurements%2FMeasureMethod.ADM_FIXED_PCT%2FdbhPhoto%2F1777662874895?alt=media&token=cdd66639-f24e-4126-afbc-cd155921b7c8 | AA10: https://firebasestorage.googleapis.com/v0/b/wt-foundation-production.appspot.com/o/measurements%2FMeasureMethod.ADM_FIXED_PCT%2FheightPhoto%2F1777662841437?alt=media&token=3168d94c-994e-4de0-a33d-0e157f15f4c2 | AF10: H8LD7fhNszdNkwPLnMnC
A11: 2026_05_01 19:21:07 | B11: 0.55698177 | C11: ADM Fixed Percent | D11: 10.594743 | E11: 0.65 | F11: 11.5 | G11: 35.310787 | H11: -120.66286 | I11: 35.310759 | J11: -120.66281 | K11: GNNIaIPthVQKUTVjjbAekjaxeHo1 | M11: iPhone13,3 | N11: 2.5.0 | O11: 12 | P11: 3 | Q11: 1 | R11: 2 | S11: 1 | T11: y | V11: tree 1 stem 2 actual | W11: W25 inventory | X11: Australian coral tree | Y11: Erythrina × sykesii | Z11: https://firebasestorage.googleapis.com/v0/b/wt-foundation-production.appspot.com/o/measurements%2FMeasureMethod.ADM_FIXED_PCT%2FdbhPhoto%2F1777663286522?alt=media&token=c16d2057-a580-4367-a653-a28797e1a1e3 | AA11: https://firebasestorage.googleapis.com/v0/b/wt-foundation-production.appspot.com/o/measurements%2FMeasureMethod.ADM_FIXED_PCT%2FheightPhoto%2F1777663267476?alt=media&token=12f14930-4aee-4dcc-9840-fe0936f0c160 | AF11: pDg7TLrvMN8a9gMFoGr7
A12: 2026_05_01 19:24:33 | B12: 0.59010245 | C12: ADM Fixed Percent | D12: 13.192575 | E12: 0.73 | F12: 13.3 | G12: 35.3108 | H12: -120.66284 | K12: GNNIaIPthVQKUTVjjbAekjaxeHo1 | M12: iPhone13,3 | N12: 2.5.0 | O12: 12 | P12: 3 | Q12: 1 | R12: 1 | S12: 1 | T12: y | V12: tree 1 stem 1 actual | W12: W25 inventory | Y12: Erythrina × sykesii | Z12: https://firebasestorage.googleapis.com/v0/b/wt-foundation-production.appspot.com/o/measurements%2FMeasureMethod.ADM_FIXED_PCT%2FdbhPhoto%2F1777663481541?alt=media&token=edd3ae3b-1aa7-47d3-af3a-a88becd9c367 | AA12: https://firebasestorage.googleapis.com/v0/b/wt-foundation-production.appspot.com/o/measurements%2FMeasureMethod.ADM_FIXED_PCT%2FheightPhoto%2F1777663473731?alt=media&token=e0517204-00cb-4eb7-a63f-5c3aff85c72b | AF12: upnP4p2r94mWOHkjRfrQ
A13: 2026_05_01 19:36:02 | B13: 0.084026725 | C13: ADM Fixed Percent | D13: 14.365968 | E13: 0.357 | F13: 13.9 | G13: 35.310842 | H13: -120.66265 | I13: 35.310785 | J13: -120.66266 | K13: GNNIaIPthVQKUTVjjbAekjaxeHo1 | M13: iPhone13,3 | N13: 2.5.0 | O13: 13 | P13: 4 | Q13: 1 | R13: 1 | S13: 1 | T13: y | V13: tree5 | W13: W25 inventory | X13: dawn redwood | Y13: Metasequoia glyptostroboides | Z13: https://firebasestorage.googleapis.com/v0/b/wt-foundation-production.appspot.com/o/measurements%2FMeasureMethod.ADM_FIXED_PCT%2FdbhPhoto%2F1777664172730?alt=media&token=7823d1da-b5e7-4aee-b193-1023c1cc8b07 | AA13: https://firebasestorage.googleapis.com/v0/b/wt-foundation-production.appspot.com/o/measurements%2FMeasureMethod.ADM_FIXED_PCT%2FheightPhoto%2F1777664172727?alt=media&token=bce67835-0e21-4734-82ae-b666fde87630 | AF13: AdGPW6fJNat70L25d0VG
A14: 2026_05_01 19:45:41 | B14: 0.32580039 | C14: ADM Fixed Percent | D14: 11.096119 | E14: 0.331 | F14: 10.5 | G14: 35.31091 | H14: -120.66265 | I14: 35.310876 | J14: -120.66271 | K14: GNNIaIPthVQKUTVjjbAekjaxeHo1 | M14: iPhone13,3 | N14: 2.5.0 | O14: 1 | P14: 5 | Q14: 1 | R14: 1 | S14: 1 | T14: y | V14: tree6 | W14: W25 inventory | X14: coast redwood | Y14: Sequoia sempervirens | Z14: https://firebasestorage.googleapis.com/v0/b/wt-foundation-production.appspot.com/o/measurements%2FMeasureMethod.ADM_FIXED_PCT%2FdbhPhoto%2F1777664754270?alt=media&token=f8de0272-7b7d-48ba-8cb8-59f0406e23b9 | AA14: https://firebasestorage.googleapis.com/v0/b/wt-foundation-production.appspot.com/o/measurements%2FMeasureMethod.ADM_FIXED_PCT%2FheightPhoto%2F1777664741672?alt=media&token=783e30f1-0d99-41e4-95ee-1434a8d4c0b6 | AF14: dhHXCufR5qh6c0P0pnB5
A15: 2026_06_18 16:58:07 | B15: 0.954154 | C15: ADM Fixed Percent | D15: 20.15184 | E15: 0.98 | F15: 19.5 | G15: 35.3109 | H15: -120.663 | I15: 35.310902 | J15: -120.66269 | K15: GNNIaIPthVQKUTVjjbAekjaxeHo1 | M15: iPhone13,3 | N15: 2.6.1 | O15: 1 | P15: 5 | Q15: 2 | R15: 1 | S15: 1 | T15: y | V15: tree 7 big redwood outside of radius | W15: W25 inventory | X15: coast redwood | Y15: Sequoia sempervirens | Z15: https://firebasestorage.googleapis.com/v0/b/wt-foundation-production.appspot.com/o/measurements%2FMeasureMethod.ADM_FIXED_PCT%2FdbhPhoto%2F1781838087715?alt=media&token=078f12dd-b707-4dda-bb15-fe739c2545ae | AA15: https://firebasestorage.googleapis.com/v0/b/wt-foundation-production.appspot.com/o/measurements%2FMeasureMethod.ADM_FIXED_PCT%2FheightPhoto%2F1781838085111?alt=media&token=4bf2f986-467c-461c-b779-692256a89fee | AE15: 4kuGNGMWqMERQyuM1Zjp | AF15: NbxDYOlRmSMoLJh2A2rR
A16: 2026_06_18 18:10:49 | B16: 0.173438 | C16: ADM Fixed Percent | D16: 5.420517 | E16: 0.201 | F16: 5.2 | G16: 35.31067 | H16: -120.663 | I16: 35.310724 | J16: -120.66286 | K16: GNNIaIPthVQKUTVjjbAekjaxeHo1 | M16: iPhone13,3 | N16: 2.6.1 | P16: 6 | Q16: 1 | R16: 1 | S16: 1 | V16: tree 1 stem 1 | W16: W25 inventory | X16: crimson bottlebrush | Y16: callistemon citrinus | Z16: https://firebasestorage.googleapis.com/v0/b/wt-foundation-production.appspot.com/o/measurements%2FMeasureMethod.ADM_FIXED_PCT%2FdbhPhoto%2F1781838116119?alt=media&token=ec9b0285-bff8-4df6-a1bb-8e6653f6def4 | AA16: https://firebasestorage.googleapis.com/v0/b/wt-foundation-production.appspot.com/o/measurements%2FMeasureMethod.ADM_FIXED_PCT%2FheightPhoto%2F1781838090373?alt=media&token=dfb04177-ee44-418a-b051-0f3ad1869251 | AF16: Fo2wuAKNXnD4rKRiR6o7
A17: 2026_05_29 18:54:18 | B17: 0.197561 | C17: ADM Fixed Percent | D17: 1.255855 | E17: 0.157 | F17: 1.3 | G17: 35.31074 | H17: -120.663 | K17: GNNIaIPthVQKUTVjjbAekjaxeHo1 | M17: iPhone13,3 | N17: 2.5.0 | P17: 6 | Q17: 1 | R17: 2 | S17: 1 | V17: tree 1 stem 2 | W17: W25 inventory | X17: lemon bottlebrush | Y17: callistemon citrinus | Z17: https://firebasestorage.googleapis.com/v0/b/wt-foundation-production.appspot.com/o/measurements%2FMeasureMethod.ADM_FIXED_PCT%2FdbhPhoto%2F1781723864974?alt=media&token=d87f2385-ecad-4d4a-9a23-d1f67e7497c5 | AA17: https://firebasestorage.googleapis.com/v0/b/wt-foundation-production.appspot.com/o/measurements%2FMeasureMethod.ADM_FIXED_PCT%2FheightPhoto%2F1781723855129?alt=media&token=e1621e56-ce47-4dba-8baa-9b355596b874 | AE17: SICXlhtBVWDzdMwXqe3y
A18: 2026_05_29 18:55:35 | B18: 0.284856 | C18: ADM Fixed Percent | D18: 1.30881 | E18: 0.186 | F18: 1.3 | G18: 35.31074 | H18: -120.663 | K18: GNNIaIPthVQKUTVjjbAekjaxeHo1 | M18: iPhone13,3 | N18: 2.5.0 | P18: 6 | Q18: 1 | R18: 3 | S18: 1 | V18: tree 1 stem 3 | W18: W25 inventory | X18: lemon bottlebrush | Y18: callistemon citrinus | Z18: https://firebasestorage.googleapis.com/v0/b/wt-foundation-production.appspot.com/o/measurements%2FMeasureMethod.ADM_FIXED_PCT%2FdbhPhoto%2F1781723869462?alt=media&token=c744b31d-d504-41fc-94f1-d26925532686 | AA18: https://firebasestorage.googleapis.com/v0/b/wt-foundation-production.appspot.com/o/measurements%2FMeasureMethod.ADM_FIXED_PCT%2FheightPhoto%2F1781723868250?alt=media&token=ececf927-4773-4012-9698-5ec793bcb485 | AE18: VxbpiFPi03j54wdRC3n0
A19: 2026_05_29 18:57:22 | B19: 0.114286 | C19: ADM Fixed Percent | D19: 2.003217 | E19: 0.116 | F19: 1.3 | G19: 35.31074 | H19: -120.663 | K19: GNNIaIPthVQKUTVjjbAekjaxeHo1 | M19: iPhone13,3 | N19: 2.5.0 | P19: 6 | Q19: 1 | R19: 4 | S19: 1 | V19: tree 1 stem 4 | W19: W25 inventory | X19: lemon bottlebrush | Y19: callistemon citrinus | Z19: https://firebasestorage.googleapis.com/v0/b/wt-foundation-production.appspot.com/o/measurements%2FMeasureMethod.ADM_FIXED_PCT%2FdbhPhoto%2F1781723871543?alt=media&token=7324d6de-8b33-414a-9ae0-50ca63434651 | AA19: https://firebasestorage.googleapis.com/v0/b/wt-foundation-production.appspot.com/o/measurements%2FMeasureMethod.ADM_FIXED_PCT%2FheightPhoto%2F1781723870255?alt=media&token=6093c2df-7a66-44f7-8028-1290e1aaf075 | AE19: DL74Y095Sv1NsiTANDQ2
A20: 2026_05_29 19:00:02 | B20: 0.17032 | C20: ADM Fixed Percent | D20: 1.259542 | E20: 0.1465 | F20: 1.3 | G20: 35.31073 | H20: -120.663 | K20: GNNIaIPthVQKUTVjjbAekjaxeHo1 | M20: iPhone13,3 | N20: 2.5.0 | P20: 6 | Q20: 1 | R20: 5 | S20: 1 | V20: tree 1 stem 5 | W20: W25 inventory | X20: lemon bottlebrush | Y20: callistemon citrinus | Z20: https://firebasestorage.googleapis.com/v0/b/wt-foundation-production.appspot.com/o/measurements%2FMeasureMethod.ADM_FIXED_PCT%2FdbhPhoto%2F1781723873542?alt=media&token=2cafb71e-3b84-42eb-ba42-77f8c5c35af9 | AA20: https://firebasestorage.googleapis.com/v0/b/wt-foundation-production.appspot.com/o/measurements%2FMeasureMethod.ADM_FIXED_PCT%2FheightPhoto%2F1781723872805?alt=media&token=ac5f89e6-0277-486f-bab8-b436ed2bff6a | AE20: DeObPws4gwnPO3gYUZCO
A21: 2026_05_29 19:04:56 | B21: 0.075853 | C21: ADM Fixed Percent | D21: 9.577039 | E21: 0.062 | F21: 8.2 | G21: 35.31089 | H21: -120.663 | I21: 35.310848 | J21: -120.66289 | K21: GNNIaIPthVQKUTVjjbAekjaxeHo1 | M21: iPhone13,3 | N21: 2.5.0 | P21: 7 | Q21: 1 | R21: 1 | S21: 1 | V21: tree 2 1 stem | W21: W25 inventory | X21: acacia | Y21: Acacia boormanii | Z21: https://firebasestorage.googleapis.com/v0/b/wt-foundation-production.appspot.com/o/measurements%2FMeasureMethod.ADM_FIXED_PCT%2FdbhPhoto%2F1781723875646?alt=media&token=05a5401f-c871-4ed7-9d8b-282af40b2817 | AA21: https://firebasestorage.googleapis.com/v0/b/wt-foundation-production.appspot.com/o/measurements%2FMeasureMethod.ADM_FIXED_PCT%2FheightPhoto%2F1781723874608?alt=media&token=be6abef2-274e-42c4-805b-b3109bc006b4 | AE21: XvBKXuVbOHc4WD3Cu2I7
A22: 2026_05_29 19:11:31 | B22: 0.106418 | C22: ADM Fixed Percent | D22: 8.892515 | E22: 0.114 | F22: 8.2 | G22: 35.3109 | H22: -120.663 | I22: 35.310877 | J22: -120.66287 | K22: GNNIaIPthVQKUTVjjbAekjaxeHo1 | M22: iPhone13,3 | N22: 2.5.0 | P22: 1 | Q22: 2 | R22: 1 | S22: 1 | V22: tree 3 stem 1 | W22: W25 inventory | X22: weeping bottlebrush | Y22: Callistemon viminalis | Z22: https://firebasestorage.googleapis.com/v0/b/wt-foundation-production.appspot.com/o/measurements%2FMeasureMethod.ADM_FIXED_PCT%2FdbhPhoto%2F1781723877603?alt=media&token=491bda0d-2c08-4a25-adb8-af9a7f1cedbb | AA22: https://firebasestorage.googleapis.com/v0/b/wt-foundation-production.appspot.com/o/measurements%2FMeasureMethod.ADM_FIXED_PCT%2FheightPhoto%2F1781723876658?alt=media&token=45ad1a83-df99-46a8-bec6-a449e5694b08 | AE22: 1tsU4YBkPtnZqmd7Q3TD
A23: 2026_05_29 19:12:55 | B23: 0.087108 | C23: ADM Fixed Percent | D23: 1.277599 | E23: 0.0955 | F23: 1.3 | G23: 35.3109 | H23: -120.663 | K23: GNNIaIPthVQKUTVjjbAekjaxeHo1 | M23: iPhone13,3 | N23: 2.5.0 | P23: 1 | Q23: 2 | R23: 2 | S23: 1 | V23: tree 3 stem 2 | W23: W25 inventory | X23: weeping bottlebrush | Y23: Callistemon viminalis | Z23: https://firebasestorage.googleapis.com/v0/b/wt-foundation-production.appspot.com/o/measurements%2FMeasureMethod.ADM_FIXED_PCT%2FdbhPhoto%2F1781723879487?alt=media&token=a5c85681-6892-4f4e-9443-cf6c16138683 | AA23: https://firebasestorage.googleapis.com/v0/b/wt-foundation-production.appspot.com/o/measurements%2FMeasureMethod.ADM_FIXED_PCT%2FheightPhoto%2F1781723878567?alt=media&token=1ff6fd1a-406d-4800-9cad-51d4d884f611 | AE23: D7qfiuoiK6pydLdvKVrY
A24: 2026_05_29 19:14:31 | B24: 0.052253 | C24: ADM Fixed Percent | D24: 1.289766 | E24: 0.055 | F24: 1.3 | G24: 35.31091 | H24: -120.663 | K24: GNNIaIPthVQKUTVjjbAekjaxeHo1 | M24: iPhone13,3 | N24: 2.5.0 | P24: 1 | Q24: 2 | R24: 3 | S24: 1 | V24: tree 3 stem 3 | W24: W25 inventory | X24: weeping bottlebrush | Y24: Callistemon viminalis | Z24: https://firebasestorage.googleapis.com/v0/b/wt-foundation-production.appspot.com/o/measurements%2FMeasureMethod.ADM_FIXED_PCT%2FdbhPhoto%2F1781723880950?alt=media&token=071339bd-d90a-4521-b3db-9efe2fc0dc51 | AA24: https://firebasestorage.googleapis.com/v0/b/wt-foundation-production.appspot.com/o/measurements%2FMeasureMethod.ADM_FIXED_PCT%2FheightPhoto%2F1781723880608?alt=media&token=eff794bf-a308-4e91-82f5-f2c78a47b238 | AE24: i30LJY7TdEMu8XUbgJYa
