Workbook

Sheet Sheet1
A1: fid | B1: OBJECTID | C1: esrignss_speed | D1: esrignss_direction | E1: esrisnsr_azimuth | F1: esrignss_positionsourcetype | G1: esrignss_receiver | H1: esrignss_h_rms | I1: esrignss_v_rms | J1: esrignss_latitude | K1: esrignss_longitude | L1: esrignss_altitude | M1: esrignss_fixdatetime | N1: GlobalID | O1: Tree_Label | P1: GT_Height | Q1: GT_DBH | R1: comon_name | S1: notes | T1: n_stems | U1: esrignss_pdop | V1: esrignss_hdop | W1: esrignss_vdop | X1: esrignss_fixtype | Y1: esrignss_correctionage | Z1: esrignss_stationid | AA1: esrignss_numsats | AB1: esrignss_avg_h_rms | AC1: esrignss_avg_v_rms | AD1: esrignss_avg_positions | AE1: esrignss_h_stddev | AF1: CreationDate | AG1: Creator | AH1: EditDate | AI1: Editor | AJ1: arrow_dbh ground truth | AK1: GT Dt | AL1: APP EQ Dt | AM1: ground_ground truth height | AN1: GT HEIGHT | AO1: APP HEIGHT | AP1: app_tree_label | AQ1: drone_lidar_height_m | AR1: crown_diam_m | AS1: GT BIOMASS | AT1: APP BIOMASS | AU1: DRONE LiDAR BIOMASS | AV1: AVG GT Dt | AW1: AVG App Dt | AX1: AVG GT H | AY1: AVG App H | AZ1: AVG GT Bio | BA1: AVG App Bio | BB1: SUM GT Bio | BC1: SUM App Bio | BD1: SUM App Bio | BE1: GT Bio kg/m^2 | BF1: App Bio kg/m^2 | BG1: App Bio kg/m^3
A2: 1 | B2: 122 | C2: 0 | D2: 305.3 | E2: 276.42606 | F2: 2 | G2: iPhone 16e | H2: 10 | I2: 19 | J2: 35.084601 | K2: -120.53658 | L2: 78.6 | M2: 2026/08/21 16:09:15.072 | N2: 92f93645-7744-4fcc-8470-322cdcf51664 | O2: 8.2 | AF2: 2026/08/21 16:11:41.618 | AG2: hosteen@calpoly.edu_CalPoly | AH2: 2026/08/21 16:11:41.618 | AI2: hosteen@calpoly.edu_CalPoly | AK2: 0.175 | AL2: 0.11238122 | AN2: 2.8 | AO2: 3.1197879 | AP2: 8.2 | AQ2: 3.2140007 | AR2: 4.4424332 | AS2: =-52.21+16.22*AK2*100-1.25*(100*AK2)^2+0.05*(100*AK2)^3-0.000712*(100*AK2)^4 -> 50.018437 | AT2: =-52.21+16.22*AL2*100-1.25*(100*AL2)^2+0.05*(100*AL2)^3-0.000712*(100*AL2)^4 -> 31.81248 | AU2: =-0.164+6.73*AR2+2.87*AQ2^2 -> 59.380103 | AV2: =AVERAGE(AK2:AK14) -> 0.17161538 | AW2: =AVERAGE(AL2:AL14) -> 0.1564943 | AX2: =AVERAGE(AN2:AN14) -> 2.7076923 | AY2: =AVERAGE(AO2:AO14) -> 2.9314578 | AZ2: =AVERAGE(AS2:AS14) -> 48.839889 | BA2: =AVERAGE(AT2:AT14) -> 41.655524 | BB2: =SUM(AS2:AS14) -> 634.91856 | BC2: =SUM(AT2:AT14) -> 541.52182 | BD2: =SUM(AU2:AU14) -> 691.47774 | BE2: =SUM(AS2:AS14)/(PI()*12.5^2) -> 1.2934455 | BF2: =SUM(AT2:AT14)/(PI()*12.5^2) -> 1.1031792 | BG2: =SUM(AU2:AU14)/(PI()*12.5^2) -> 1.4086669
A3: 2 | B3: 123 | C3: 0.3704 | D3: 321.8 | E3: 284.9122 | F3: 2 | G3: iPhone 16e | H3: 10 | I3: 19 | J3: 35.084636 | K3: -120.53653 | L3: 77.6 | M3: 2026/08/21 16:12:27.072 | N3: 73641b55-a6d3-4057-9c92-56524b048e94 | O3: 8.3 | AF3: 2026/08/21 16:15:18.595 | AG3: hosteen@calpoly.edu_CalPoly | AH3: 2026/08/21 16:15:18.595 | AI3: hosteen@calpoly.edu_CalPoly | AK3: 0.17 | AL3: 0.16485037 | AN3: 2.7 | AO3: 3.3198817 | AP3: 8.3 | AQ3: 2.9129987 | AR3: 4.9184908 | AS3: =-52.21+16.22*AK3*100-1.25*(100*AK3)^2+0.05*(100*AK3)^3-0.000712*(100*AK3)^4 -> 48.463048 | AT3: =-52.21+16.22*AL3*100-1.25*(100*AL3)^2+0.05*(100*AL3)^3-0.000712*(100*AL3)^4 -> 46.895181 | AU3: =-0.164+6.73*AR3+2.87*AQ3^2 -> 57.291004
A4: 3 | B4: 124 | C4: 0.1852 | D4: 267.9 | E4: 168.98332 | F4: 2 | G4: iPhone 16e | H4: 10 | I4: 19 | J4: 35.084674 | K4: -120.53649 | L4: 79.1 | M4: 2026/08/21 16:16:41.062 | N4: 5043a958-f15e-450b-897e-fa5eb1b2a3b4 | O4: 8.4 | Q4: 21.5 | T4: 2 | AF4: 2026/08/21 16:17:45.300 | AG4: hosteen@calpoly.edu_CalPoly | AH4: 2026/08/21 16:20:20.234 | AI4: hosteen@calpoly.edu_CalPoly | AJ4: 21.5 | AK4: 0.215 | AL4: 0.21558288 | AN4: 2.9 | AO4: 3.4619977 | AP4: 8.4 | AQ4: 3.2299979 | AR4: 5.046265 | AS4: =-52.21+16.22*AK4*100-1.25*(100*AK4)^2+0.05*(100*AK4)^3-0.000712*(100*AK4)^4 -> 63.489606 | AT4: =-52.21+16.22*AL4*100-1.25*(100*AL4)^2+0.05*(100*AL4)^3-0.000712*(100*AL4)^4 -> 63.693788 | AU4: =-0.164+6.73*AR4+2.87*AQ4^2 -> 63.739747
A5: 4 | B5: 125 | C5: 0.3704 | D5: 359.3 | E5: 330.41702 | F5: 2 | G5: iPhone 16e | H5: 10 | I5: 19 | J5: 35.084701 | K5: -120.53646 | L5: 80 | M5: 2026/08/21 16:22:01.069 | N5: 7de0d8b8-5da3-42f3-bc27-d7203512a4aa | O5: 8.5 | AF5: 2026/08/21 16:23:10.553 | AG5: hosteen@calpoly.edu_CalPoly | AH5: 2026/08/21 16:23:39.748 | AI5: hosteen@calpoly.edu_CalPoly | AK5: 0.184 | AL5: 0.12034645 | AN5: 3.2 | AO5: 3.3775017 | AP5: 8.5 | AQ5: 3.5669973 | AR5: 5.1400117 | AS5: =-52.21+16.22*AK5*100-1.25*(100*AK5)^2+0.05*(100*AK5)^3-0.000712*(100*AK5)^4 -> 52.901714 | AT5: =-52.21+16.22*AL5*100-1.25*(100*AL5)^2+0.05*(100*AL5)^3-0.000712*(100*AL5)^4 -> 34.166314 | AU5: =-0.164+6.73*AR5+2.87*AQ5^2 -> 70.944637
A6: 5 | B6: 127 | C6: 0 | D6: 126.7 | E6: 240.17079 | F6: 2 | G6: iPhone 16e | H6: 10 | I6: 19 | J6: 35.084561 | K6: -120.53652 | L6: 78.9 | M6: 2026/08/21 16:27:14.067 | N6: 47f46abe-7ae2-49c2-84f8-e53071ead6e0 | O6: 8.7 | Q6: 17.7 | AF6: 2026/08/21 16:28:59.181 | AG6: hosteen@calpoly.edu_CalPoly | AH6: 2026/08/21 16:28:59.181 | AI6: hosteen@calpoly.edu_CalPoly | AJ6: 17.7 | AK6: 0.177 | AL6: 0.16843937 | AN6: 3.1 | AO6: 3.0354292 | AP6: 8.7 | AQ6: 2.9599984 | AR6: 4.7539459 | AS6: =-52.21+16.22*AK6*100-1.25*(100*AK6)^2+0.05*(100*AK6)^3-0.000712*(100*AK6)^4 -> 50.649906 | AT6: =-52.21+16.22*AL6*100-1.25*(100*AL6)^2+0.05*(100*AL6)^3-0.000712*(100*AL6)^4 -> 47.984307 | AU6: =-0.164+6.73*AR6+2.87*AQ6^2 -> 56.97582
A7: 6 | B7: 128 | C7: 0.3704 | D7: 34.3 | E7: 161.34941 | F7: 2 | G7: iPhone 16e | H7: 10 | I7: 19 | J7: 35.084593 | K7: -120.53648 | L7: 79.2 | M7: 2026/08/21 16:29:24.073 | N7: 1c68bc34-d03b-4704-84d2-9a600afa5a27 | O7: 8.8 | Q7: 18.4 | AF7: 2026/08/21 16:31:35.688 | AG7: hosteen@calpoly.edu_CalPoly | AH7: 2026/08/21 16:31:35.688 | AI7: hosteen@calpoly.edu_CalPoly | AJ7: 18.4 | AK7: 0.184 | AL7: 0.1683897 | AN7: 3 | AO7: 3.2395394 | AP7: 8.8 | AQ7: 3.0080006 | AR7: 4.8533423 | AS7: =-52.21+16.22*AK7*100-1.25*(100*AK7)^2+0.05*(100*AK7)^3-0.000712*(100*AK7)^4 -> 52.901714 | AT7: =-52.21+16.22*AL7*100-1.25*(100*AL7)^2+0.05*(100*AL7)^3-0.000712*(100*AL7)^4 -> 47.969124 | AU7: =-0.164+6.73*AR7+2.87*AQ7^2 -> 58.466948
A8: 7 | B8: 129 | C8: 0 | D8: 96.8 | E8: 30.637283 | F8: 2 | G8: iPhone 16e | H8: 10 | I8: 19 | J8: 35.084614 | K8: -120.53644 | L8: 78 | M8: 2026/08/21 16:31:59.072 | N8: ad7861a4-701f-42f3-9e3a-5fb57434c3a2 | O8: 8.9 | Q8: 18.5 | AF8: 2026/08/21 16:33:37.418 | AG8: hosteen@calpoly.edu_CalPoly | AH8: 2026/08/21 16:33:37.418 | AI8: hosteen@calpoly.edu_CalPoly | AJ8: 18.5 | AK8: 0.185 | AL8: 0.18307942 | AN8: 2.8 | AO8: 3.3693588 | AP8: 8.9 | AQ8: 2.9569983 | AR8: 4.3336224 | AS8: =-52.21+16.22*AK8*100-1.25*(100*AK8)^2+0.05*(100*AK8)^3-0.000712*(100*AK8)^4 -> 53.228586 | AT8: =-52.21+16.22*AL8*100-1.25*(100*AL8)^2+0.05*(100*AL8)^3-0.000712*(100*AL8)^4 -> 52.601929 | AU8: =-0.164+6.73*AR8+2.87*AQ8^2 -> 54.096097
A9: 8 | B9: 130 | C9: 0.1852 | D9: 48.4 | E9: 128.14104 | F9: 2 | G9: iPhone 16e | H9: 10 | I9: 19 | J9: 35.084651 | K9: -120.5364 | L9: 81.5 | M9: 2026/08/21 16:35:07.076 | N9: 04d12d77-2d9f-40c8-9b03-449954bb0220 | O9: 8.10 | Q9: 16.6 | AF9: 2026/08/21 16:35:27.956 | AG9: hosteen@calpoly.edu_CalPoly | AH9: 2026/08/21 16:39:39.159 | AI9: hosteen@calpoly.edu_CalPoly | AJ9: 16.6 | AK9: 0.166 | AL9: 0.27806708 | AN9: 2.6 | AO9: 2.4037929 | AP9: 8.10 | AQ9: 2.5780001 | AR9: 3.9493271 | AS9: =-52.21+16.22*AK9*100-1.25*(100*AK9)^2+0.05*(100*AK9)^3-0.000712*(100*AK9)^4 -> 47.242281 | AT9: =-52.21+16.22*AL9*100-1.25*(100*AL9)^2+0.05*(100*AL9)^3-0.000712*(100*AL9)^4 -> 81.64881 | AU9: =-0.164+6.73*AR9+2.87*AQ9^2 -> 45.489233
A10: 9 | B10: 132 | C10: 0.1852 | D10: 109.6 | E10: 148.77811 | F10: 2 | G10: iPhone 16e | H10: 10 | I10: 19 | J10: 35.084529 | K10: -120.53646 | L10: 81.2 | M10: 2026/08/21 16:42:46.075 | N10: 8884e29c-7d77-474a-8b96-530a4e20c9c8 | O10: 8.12 | Q10: 18.3 | AF10: 2026/08/21 16:44:44.988 | AG10: hosteen@calpoly.edu_CalPoly | AH10: 2026/08/21 16:44:44.988 | AI10: hosteen@calpoly.edu_CalPoly | AJ10: 18.3 | AK10: 0.183 | AL10: 0.16734623 | AN10: 3 | AO10: 2.9695661 | AP10: 8.12 | AQ10: 2.9310014 | AR10: 4.478116 | AS10: =-52.21+16.22*AK10*100-1.25*(100*AK10)^2+0.05*(100*AK10)^3-0.000712*(100*AK10)^4 -> 52.576116 | AT10: =-52.21+16.22*AL10*100-1.25*(100*AL10)^2+0.05*(100*AL10)^3-0.000712*(100*AL10)^4 -> 47.65085 | AU10: =-0.164+6.73*AR10+2.87*AQ10^2 -> 54.629229
A11: 10 | B11: 133 | C11: 0 | D11: 60.6 | E11: 88.771454 | F11: 2 | G11: iPhone 16e | H11: 10 | I11: 19 | J11: 35.084553 | K11: -120.53642 | L11: 80 | M11: 2026/08/21 16:45:06.058 | N11: 21a01b4e-2e56-4d70-be40-754514b716fc | O11: 8.13 | Q11: 18.5 | AF11: 2026/08/21 16:46:51.455 | AG11: hosteen@calpoly.edu_CalPoly | AH11: 2026/08/21 16:46:51.455 | AI11: hosteen@calpoly.edu_CalPoly | AJ11: 18.5 | AK11: 0.185 | AL11: 0.17482201 | AN11: 2.8 | AO11: 3.0462446 | AP11: 8.13 | AQ11: 3.118 | AR11: 4.5486418 | AS11: =-52.21+16.22*AK11*100-1.25*(100*AK11)^2+0.05*(100*AK11)^3-0.000712*(100*AK11)^4 -> 53.228586 | AT11: =-52.21+16.22*AL11*100-1.25*(100*AL11)^2+0.05*(100*AL11)^3-0.000712*(100*AL11)^4 -> 49.962497 | AU11: =-0.164+6.73*AR11+2.87*AQ11^2 -> 58.350282
A12: 11 | B12: 134 | C12: 0 | D12: 77.2 | E12: 197.86888 | F12: 2 | G12: iPhone 16e | H12: 10 | I12: 19 | J12: 35.084583 | K12: -120.53638 | L12: 80.3 | M12: 2026/08/21 16:47:32.074 | N12: f0a7cab6-6cc5-4047-a1b8-0244eac58b73 | O12: 8.14 | Q12: 16.5 | T12: 2 | AF12: 2026/08/21 16:51:26.124 | AG12: hosteen@calpoly.edu_CalPoly | AH12: 2026/08/21 16:51:26.124 | AI12: hosteen@calpoly.edu_CalPoly | AJ12: 16.5 | AK12: 0.165 | AL12: 0.13065045 | AN12: 2.5 | AO12: 2.1789553 | AP12: 8.14 | AQ12: 2.3939989 | AR12: 3.7424103 | AS12: =-52.21+16.22*AK12*100-1.25*(100*AK12)^2+0.05*(100*AK12)^3-0.000712*(100*AK12)^4 -> 46.940266 | AT12: =-52.21+16.22*AL12*100-1.25*(100*AL12)^2+0.05*(100*AL12)^3-0.000712*(100*AL12)^4 -> 37.097447 | AU12: =-0.164+6.73*AR12+2.87*AQ12^2 -> 41.471053
A13: 12 | B13: 202 | C13: 0.5556 | D13: 157.5 | E13: 159.23143 | F13: 2 | G13: iPhone 16e | H13: 10 | I13: 19 | J13: 35.084689 | K13: -120.53636 | L13: 82.3 | M13: 2026/10/04 12:11:13.072 | N13: b51aaea7-aab1-4a71-9cbf-d3072b1c063a | O13: 8.e | Q13: 17.8 | AF13: 2026/10/04 12:13:11.891 | AG13: hosteen@calpoly.edu_CalPoly | AH13: 2026/10/04 12:13:11.891 | AI13: hosteen@calpoly.edu_CalPoly | AJ13: 17.8 | AK13: 0.178 | AL13: 0.1427863 | AN13: 2.4 | AO13: 2.9545071 | AP13: 8.e | AQ13: 2.9580028 | AR13: 4.5486418 | AS13: =-52.21+16.22*AK13*100-1.25*(100*AK13)^2+0.05*(100*AK13)^3-0.000712*(100*AK13)^4 -> 50.967639 | AT13: =-52.21+16.22*AL13*100-1.25*(100*AL13)^2+0.05*(100*AL13)^3-0.000712*(100*AL13)^4 -> 40.500589 | AU13: =-0.164+6.73*AR13+2.87*AQ13^2 -> 55.56023
A14: 13 | B14: 135 | C14: 0 | D14: 97.9 | E14: 132.01732 | F14: 2 | G14: iPhone 16e | H14: 10 | I14: 19 | J14: 35.084607 | K14: -120.53635 | L14: 82.6 | M14: 2026/08/21 16:53:19.074 | N14: 7e4c6374-c1f2-4af9-94eb-6574487ea3d2 | O14: 8.15 | AF14: 2026/08/21 16:57:08.387 | AG14: hosteen@calpoly.edu_CalPoly | AH14: 2026/10/05 13:22:08.515 | AI14: kdavis99@calpoly.edu_CalPoly | AK14: 0.064 | AL14: 0.007684462 | AN14: 1.4 | AO14: 1.6323889 | AP14: 8.15 | AQ14: 1.6329967 | AR14: 1.1283792 | AS14: =-52.21+16.22*AK14*100-1.25*(100*AK14)^2+0.05*(100*AK14)^3-0.000712*(100*AK14)^4 -> 12.310662 | AT14: =-52.21+16.22*AL14*100-1.25*(100*AL14)^2+0.05*(100*AL14)^3-0.000712*(100*AL14)^4 -> -40.461499 | AU14: =-0.164+6.73*AR14+2.87*AQ14^2 -> 15.083358
A15: 16 | B15: 107 | C15: 0.7408 | D15: 83.8 | E15: 130.88153 | F15: 2 | G15: iPhone 16e | H15: 10 | I15: 19 | J15: 35.084956 | K15: -120.53611 | L15: 79.1 | M15: 2026/08/21 15:09:24.079 | N15: 7d2d4c66-8e15-4669-8b30-66ea334b08d3 | O15: 7.2 | Q15: 21 | AF15: 2026/08/21 15:10:58.169 | AG15: hosteen@calpoly.edu_CalPoly | AH15: 2026/08/21 15:10:58.169 | AI15: hosteen@calpoly.edu_CalPoly | AJ15: 21 | AK15: 0.21 | AL15: 0.21381452 | AN15: 2.9 | AO15: 3.8535931 | AP15: 7.2 | AQ15: 3.5449979 | AR15: 5.7536274 | AS15: =-52.21+16.22*AK15*100-1.25*(100*AK15)^2+0.05*(100*AK15)^3-0.000712*(100*AK15)^4 -> 61.739528 | AT15: =-52.21+16.22*AL15*100-1.25*(100*AL15)^2+0.05*(100*AL15)^3-0.000712*(100*AL15)^4 -> 63.074355 | AU15: =-0.164+6.73*AR15+2.87*AQ15^2 -> 74.625232 | AV15: =AVERAGE(AK15:AK27) -> 0.19030769 | AW15: =AVERAGE(AL15:AL27) -> 0.16458972 | AX15: =AVERAGE(AN15:AN27) -> 3.0230769 | AY15: =AVERAGE(AO15:AO27) -> 3.4595586 | AZ15: =AVERAGE(AS15:AS27) -> 55.146241 | BA15: =AVERAGE(AT15:AT27) -> 47.189597 | BB15: =SUM(AS15:AS27) -> 716.90114 | BC15: =SUM(AT15:AT27) -> 613.46476 | BD15: =SUM(AU15:AU27) -> 832.3193 | BE15: =SUM(AS15:AS27)/(PI()*12.5^2) -> 1.460459 | BF15: =SUM(AT15:AT27)/(PI()*12.5^2) -> 1.2497402 | BG15: =SUM(AU15:AU27)/(PI()*12.5^2) -> 1.695587
A16: 17 | B16: 108 | C16: 0.1852 | D16: 68.6 | E16: 36.101738 | F16: 2 | G16: iPhone 16e | H16: 10 | I16: 19 | J16: 35.084981 | K16: -120.53607 | L16: 79.6 | M16: 2026/08/21 15:11:18.063 | N16: ba6a38bd-8a32-4c42-8b51-9ff8524b5f9e | O16: 7.3 | Q16: 21.1 | AF16: 2026/08/21 15:14:35.453 | AG16: hosteen@calpoly.edu_CalPoly | AH16: 2026/08/21 15:14:35.453 | AI16: hosteen@calpoly.edu_CalPoly | AJ16: 21.1 | AK16: 0.211 | AL16: 0.2308056 | AN16: 3 | AO16: 3.6996357 | AP16: 7.3 | AQ16: 3.427001 | AR16: 5.1400117 | AS16: =-52.21+16.22*AK16*100-1.25*(100*AK16)^2+0.05*(100*AK16)^3-0.000712*(100*AK16)^4 -> 62.089146 | AT16: =-52.21+16.22*AL16*100-1.25*(100*AL16)^2+0.05*(100*AL16)^3-0.000712*(100*AL16)^4 -> 68.978197 | AU16: =-0.164+6.73*AR16+2.87*AQ16^2 -> 68.134523
A17: 18 | B17: 109 | C17: 0 | D17: 188.7 | E17: 174.76695 | F17: 2 | G17: iPhone 16e | H17: 10 | I17: 19 | J17: 35.085014 | K17: -120.53602 | L17: 80.5 | M17: 2026/08/21 15:14:56.075 | N17: d0edea7f-13d0-433d-aa0d-6412089639b3 | O17: 7.4 | Q17: 17.9 | AF17: 2026/08/21 15:16:40.002 | AG17: hosteen@calpoly.edu_CalPoly | AH17: 2026/08/21 15:16:40.002 | AI17: hosteen@calpoly.edu_CalPoly | AJ17: 17.9 | AK17: 0.179 | AL17: 0.17578262 | AN17: 3 | AO17: 3.3081775 | AP17: 7.4 | AQ17: 3.2229981 | AR17: 4.5486418 | AS17: =-52.21+16.22*AK17*100-1.25*(100*AK17)^2+0.05*(100*AK17)^3-0.000712*(100*AK17)^4 -> 51.286702 | AT17: =-52.21+16.22*AL17*100-1.25*(100*AL17)^2+0.05*(100*AL17)^3-0.000712*(100*AL17)^4 -> 50.264903 | AU17: =-0.164+6.73*AR17+2.87*AQ17^2 -> 60.261107
A18: 19 | B18: 110 | C18: 0 | D18: 315.2 | E18: 39.603729 | F18: 2 | G18: iPhone 16e | H18: 10 | I18: 19 | J18: 35.085038 | K18: -120.53598 | L18: 81.6 | M18: 2026/08/21 15:17:02.083 | N18: 301be4c2-213b-4fe2-8f28-cabacc5f739d | O18: 7.5 | AF18: 2026/08/21 15:19:02.144 | AG18: hosteen@calpoly.edu_CalPoly | AH18: 2026/08/21 15:19:02.144 | AI18: hosteen@calpoly.edu_CalPoly | AK18: 0.185 | AL18: 0.17974123 | AN18: 3.4 | AO18: 3.7452636 | AP18: 7.5 | AQ18: 3.572 | AR18: 5.3225539 | AS18: =-52.21+16.22*AK18*100-1.25*(100*AK18)^2+0.05*(100*AK18)^3-0.000712*(100*AK18)^4 -> 53.228586 | AT18: =-52.21+16.22*AL18*100-1.25*(100*AL18)^2+0.05*(100*AL18)^3-0.000712*(100*AL18)^4 -> 51.524055 | AU18: =-0.164+6.73*AR18+2.87*AQ18^2 -> 72.275646
A19: 20 | B19: 112 | C19: 0.5556 | D19: 117.3 | E19: 159.061 | F19: 2 | G19: iPhone 16e | H19: 10 | I19: 19 | J19: 35.084904 | K19: -120.53605 | L19: 81.4 | M19: 2026/08/21 15:24:07.063 | N19: d036f44a-c49e-4482-af79-01e8408bf89c | O19: 7.7 | Q19: 17.8 | AF19: 2026/08/21 15:26:00.258 | AG19: hosteen@calpoly.edu_CalPoly | AH19: 2026/08/21 15:26:00.258 | AI19: hosteen@calpoly.edu_CalPoly | AJ19: 17.8 | AK19: 0.178 | AL19: 0.066998458 | AN19: 3 | AO19: 3.4119825 | AP19: 7.7 | AQ19: 3.2819996 | AR19: 4.7873074 | AS19: =-52.21+16.22*AK19*100-1.25*(100*AK19)^2+0.05*(100*AK19)^3-0.000712*(100*AK19)^4 -> 50.967639 | AT19: =-52.21+16.22*AL19*100-1.25*(100*AL19)^2+0.05*(100*AL19)^3-0.000712*(100*AL19)^4 -> 13.954066 | AU19: =-0.164+6.73*AR19+2.87*AQ19^2 -> 62.968845
A20: 21 | B20: 113 | C20: 0.1852 | D20: 356.3 | E20: 85.497734 | F20: 2 | G20: iPhone 16e | H20: 10 | I20: 19 | J20: 35.084935 | K20: -120.536 | L20: 80.4 | M20: 2026/08/21 15:26:09.080 | N20: 555a7683-56ea-4ad3-bbca-9c6f6bff816d | O20: 7.8 | Q20: 24 | AF20: 2026/08/21 15:29:14.724 | AG20: hosteen@calpoly.edu_CalPoly | AH20: 2026/08/21 15:29:14.724 | AI20: hosteen@calpoly.edu_CalPoly | AJ20: 24 | AK20: 0.24 | AL20: 0.20333852 | AN20: 3.1 | AO20: 3.5706685 | AP20: 7.8 | AQ20: 3.3660026 | AR20: 4.8533423 | AS20: =-52.21+16.22*AK20*100-1.25*(100*AK20)^2+0.05*(100*AK20)^3-0.000712*(100*AK20)^4 -> 72.045488 | AT20: =-52.21+16.22*AL20*100-1.25*(100*AL20)^2+0.05*(100*AL20)^3-0.000712*(100*AL20)^4 -> 59.42144 | AU20: =-0.164+6.73*AR20+2.87*AQ20^2 -> 65.016017
A21: 22 | B21: 114 | C21: 0.1852 | D21: 182.5 | E21: 52.540359 | F21: 2 | G21: iPhone 16e | H21: 10 | I21: 19 | J21: 35.08497 | K21: -120.53596 | L21: 80.6 | M21: 2026/08/21 15:29:58.080 | N21: 7a3d4fe6-fb90-4e4f-849c-a1469226a436 | O21: 7.9 | Q21: 19.7 | AF21: 2026/08/21 15:31:56.191 | AG21: hosteen@calpoly.edu_CalPoly | AH21: 2026/08/21 15:31:56.191 | AI21: hosteen@calpoly.edu_CalPoly | AJ21: 19.7 | AK21: 0.197 | AL21: 0.21202961 | AN21: 3.3 | AO21: 3.7971451 | AP21: 7.9 | AQ21: 3.5950024 | AR21: 5.1708829 | AS21: =-52.21+16.22*AK21*100-1.25*(100*AK21)^2+0.05*(100*AK21)^3-0.000712*(100*AK21)^4 -> 57.24309 | AT21: =-52.21+16.22*AL21*100-1.25*(100*AL21)^2+0.05*(100*AL21)^3-0.000712*(100*AL21)^4 -> 62.449387 | AU21: =-0.164+6.73*AR21+2.87*AQ21^2 -> 71.728044
A22: 23 | B22: 115 | C22: 0 | D22: 289.7 | E22: 118.45702 | F22: 2 | G22: iPhone 16e | H22: 10 | I22: 19 | J22: 35.084993 | K22: -120.53592 | L22: 79.6 | M22: 2026/08/21 15:32:06.075 | N22: e36dc07f-5732-409e-a961-576167bf947f | O22: 7.10 | Q22: 19.5 | AF22: 2026/08/21 15:34:11.750 | AG22: hosteen@calpoly.edu_CalPoly | AH22: 2026/08/21 15:34:11.750 | AI22: hosteen@calpoly.edu_CalPoly | AJ22: 19.5 | AK22: 0.195 | AL22: 0.19809883 | AN22: 3 | AO22: 3.4503734 | AP22: 7.10 | AQ22: 3.3560007 | AR22: 4.7203487 | AS22: =-52.21+16.22*AK22*100-1.25*(100*AK22)^2+0.05*(100*AK22)^3-0.000712*(100*AK22)^4 -> 56.563126 | AT22: =-52.21+16.22*AL22*100-1.25*(100*AL22)^2+0.05*(100*AL22)^3-0.000712*(100*AL22)^4 -> 57.618293 | AU22: =-0.164+6.73*AR22+2.87*AQ22^2 -> 63.928012
A23: 24 | B23: 118 | C23: 0.1852 | D23: 92 | E23: 166.61855 | F23: 2 | G23: iPhone 16e | H23: 10 | I23: 19 | J23: 35.084899 | K23: -120.53595 | L23: 81.8 | M23: 2026/08/21 15:41:11.075 | N23: 406b1d17-6d0a-4a4b-9d33-b4058e709f87 | O23: 7.13 | Q23: 16.6 | AF23: 2026/08/21 15:45:25.924 | AG23: hosteen@calpoly.edu_CalPoly | AH23: 2026/08/21 15:45:25.924 | AI23: hosteen@calpoly.edu_CalPoly | AJ23: 16.6 | AK23: 0.166 | AL23: 0.10635572 | AN23: 2.9 | AO23: 3.223062 | AP23: 7.13 | AQ23: 3.165 | AR23: 4.7873074 | AS23: =-52.21+16.22*AK23*100-1.25*(100*AK23)^2+0.05*(100*AK23)^3-0.000712*(100*AK23)^4 -> 47.242281 | AT23: =-52.21+16.22*AL23*100-1.25*(100*AL23)^2+0.05*(100*AL23)^3-0.000712*(100*AL23)^4 -> 29.946978 | AU23: =-0.164+6.73*AR23+2.87*AQ23^2 -> 60.804014
A24: 25 | B24: 119 | C24: 0 | D24: 230.7 | E24: 168.41551 | F24: 2 | G24: iPhone 16e | H24: 10 | I24: 19 | J24: 35.084929 | K24: -120.53591 | L24: 81.3 | M24: 2026/08/21 15:47:21.074 | N24: ff5ab09b-70e2-4e53-ba7a-5b4ae111482f | O24: 7.14 | Q24: 18.8 | AF24: 2026/08/21 15:49:17.157 | AG24: hosteen@calpoly.edu_CalPoly | AH24: 2026/08/21 15:49:17.157 | AI24: hosteen@calpoly.edu_CalPoly | AJ24: 18.8 | AK24: 0.188 | AL24: 0.09094633 | AN24: 3.1 | AO24: 3.369709 | AP24: 7.14 | AQ24: 3.3310027 | AR24: 4.4424332 | AS24: =-52.21+16.22*AK24*100-1.25*(100*AK24)^2+0.05*(100*AK24)^3-0.000712*(100*AK24)^4 -> 54.216678 | AT24: =-52.21+16.22*AL24*100-1.25*(100*AL24)^2+0.05*(100*AL24)^3-0.000712*(100*AL24)^4 -> 24.655405 | AU24: =-0.164+6.73*AR24+2.87*AQ24^2 -> 61.577888
A25: 26 | B25: 203 | C25: 0.3704 | D25: 151.8 | E25: 99.042175 | F25: 2 | G25: iPhone 16e | H25: 10 | I25: 19 | J25: 35.085083 | K25: -120.53604 | L25: 79.4 | M25: 2026/10/04 12:15:28.076 | N25: 56b59432-4605-479b-9515-67ba28210328 | O25: 7.b | Q25: 18.4 | AF25: 2026/10/04 12:17:42.971 | AG25: hosteen@calpoly.edu_CalPoly | AH25: 2026/10/04 12:17:42.971 | AI25: hosteen@calpoly.edu_CalPoly | AJ25: 18.4 | AK25: 0.184 | AL25: 0.16617045 | AN25: 3.2 | AO25: 3.5685458 | AP25: 7.b | AQ25: 3.4009991 | AR25: 4.7873074 | AS25: =-52.21+16.22*AK25*100-1.25*(100*AK25)^2+0.05*(100*AK25)^3-0.000712*(100*AK25)^4 -> 52.901714 | AT25: =-52.21+16.22*AL25*100-1.25*(100*AL25)^2+0.05*(100*AL25)^3-0.000712*(100*AL25)^4 -> 47.293884 | AU25: =-0.164+6.73*AR25+2.87*AQ25^2 -> 65.251279
A26: 27 | B26: 204 | C26: 0.1852 | D26: 165.9 | E26: 115.57558 | F26: 2 | G26: iPhone 16e | H26: 10 | I26: 19 | J26: 35.085055 | K26: -120.53608 | L26: 79.5 | M26: 2026/10/04 12:18:26.077 | N26: bf177a57-350e-42e2-bd91-0da437fba051 | O26: 7.a | Q26: 18.1 | AF26: 2026/10/04 12:20:05.379 | AG26: hosteen@calpoly.edu_CalPoly | AH26: 2026/10/04 12:20:05.379 | AI26: hosteen@calpoly.edu_CalPoly | AJ26: 18.1 | AK26: 0.181 | AL26: 0.11939073 | AN26: 2.9 | AO26: 3.2764475 | AP26: 7.a | AQ26: 3.0769982 | AR26: 4.7873074 | AS26: =-52.21+16.22*AK26*100-1.25*(100*AK26)^2+0.05*(100*AK26)^3-0.000712*(100*AK26)^4 -> 51.928792 | AT26: =-52.21+16.22*AL26*100-1.25*(100*AL26)^2+0.05*(100*AL26)^3-0.000712*(100*AL26)^4 -> 33.889115 | AU26: =-0.164+6.73*AR26+2.87*AQ26^2 -> 59.227504
A27: 28 | B27: 205 | C27: 0.3704 | D27: 106.3 | E27: 24.311255 | F27: 2 | G27: iPhone 16e | H27: 10 | I27: 19 | J27: 35.084956 | K27: -120.53587 | L27: 81.8 | M27: 2026/10/04 12:21:05.059 | N27: 5fd53596-fcf2-4478-9a68-2d8cda271598 | O27: 7.c | P27: 2.5 | Q27: 16 | AF27: 2026/10/04 12:22:46.070 | AG27: hosteen@calpoly.edu_CalPoly | AH27: 2026/10/04 12:22:46.070 | AI27: hosteen@calpoly.edu_CalPoly | AJ27: 16 | AK27: 0.16 | AL27: 0.1761937 | AM27: 2.5 | AN27: 2.5 | AO27: 2.6996584 | AP27: 7.c | AQ27: 2.6289976 | AR27: 3.9894228 | AS27: =-52.21+16.22*AK27*100-1.25*(100*AK27)^2+0.05*(100*AK27)^3-0.000712*(100*AK27)^4 -> 45.448368 | AT27: =-52.21+16.22*AL27*100-1.25*(100*AL27)^2+0.05*(100*AL27)^3-0.000712*(100*AL27)^4 -> 50.394688 | AU27: =-0.164+6.73*AR27+2.87*AQ27^2 -> 46.521188
A28: 30 | B28: 91 | C28: 0 | D28: 254.2 | E28: 196.78197 | F28: 2 | G28: iPhone 16e | H28: 10 | I28: 19 | J28: 35.085397 | K28: -120.53562 | L28: 82.1 | M28: 2026/08/21 14:14:39.073 | N28: 63ac34da-b2ed-4e3f-bae9-f54e3e43c31a | O28: 6.3 | Q28: 17.7 | AF28: 2026/08/21 14:16:38.990 | AG28: hosteen@calpoly.edu_CalPoly | AH28: 2026/08/21 14:16:38.990 | AI28: hosteen@calpoly.edu_CalPoly | AJ28: 17.7 | AK28: 0.177 | AL28: 0.092966374 | AN28: 2.7 | AO28: 3.4502163 | AP28: 6.3 | AQ28: 3.3709967 | AR28: 4.7203487 | AS28: =-52.21+16.22*AK28*100-1.25*(100*AK28)^2+0.05*(100*AK28)^3-0.000712*(100*AK28)^4 -> 50.649906 | AT28: =-52.21+16.22*AL28*100-1.25*(100*AL28)^2+0.05*(100*AL28)^3-0.000712*(100*AL28)^4 -> 25.402935 | AU28: =-0.164+6.73*AR28+2.87*AQ28^2 -> 64.217533 | AV28: =AVERAGE(AK28:AK41) -> 0.1745 | AW28: =AVERAGE(AL28:AM41) -> 0.34542957 | AX28: =AVERAGE(AN28:AN41) -> 3.1857143 | AY28: =AVERAGE(AO28:AO41) -> 3.6731345 | AZ28: =AVERAGE(AS28:AS41) -> 50.005505 | BA28: =AVERAGE(AT28:AT41) -> 35.494886 | BB28: =SUM(AS28:AS41) -> 700.07707 | BC28: =SUM(AT28:AT41) -> 496.92841 | BD28: =SUM(AU28:AU41) -> 959.11472 | BE28: =SUM(AS28:AS41)/(PI()*12.5^2) -> 1.4261853 | BF28: =SUM(AT28:AT41)/(PI()*12.5^2) -> 1.0123342 | BG28: =SUM(AU28:AU41)/(PI()*12.5^2) -> 1.9538925
A29: 31 | B29: 93 | C29: 0 | D29: 175 | E29: 213.32689 | F29: 2 | G29: iPhone 16e | H29: 10 | I29: 19 | J29: 35.08528 | K29: -120.53565 | L29: 84.7 | M29: 2026/08/21 14:21:01.058 | N29: d03a3ee0-c162-4d31-b49f-c13b54387060 | O29: 6.5 | AF29: 2026/08/21 14:23:07.882 | AG29: hosteen@calpoly.edu_CalPoly | AH29: 2026/08/21 14:23:07.882 | AI29: hosteen@calpoly.edu_CalPoly | AK29: 0.174 | AL29: 0.22639343 | AN29: 2.9 | AO29: 3.5511067 | AP29: 6.5 | AQ29: 3.3959999 | AR29: 5.3523723 | AS29: =-52.21+16.22*AK29*100-1.25*(100*AK29)^2+0.05*(100*AK29)^3-0.000712*(100*AK29)^4 -> 49.704704 | AT29: =-52.21+16.22*AL29*100-1.25*(100*AL29)^2+0.05*(100*AL29)^3-0.000712*(100*AL29)^4 -> 67.463268 | AU29: =-0.164+6.73*AR29+2.87*AQ29^2 -> 68.956646
A30: 32 | B30: 94 | C30: 0.1852 | D30: 122 | E30: 254.34665 | F30: 2 | G30: iPhone 16e | H30: 10 | I30: 19 | J30: 35.085316 | K30: -120.5356 | L30: 81.7 | M30: 2026/08/21 14:23:35.073 | N30: 00e9ab9b-aecd-4dc1-93c0-73d83c0a29ca | O30: 6.6 | P30: 3.4 | Q30: 17.2 | AF30: 2026/08/21 14:25:17.727 | AG30: hosteen@calpoly.edu_CalPoly | AH30: 2026/08/21 14:25:17.727 | AI30: hosteen@calpoly.edu_CalPoly | AJ30: 17.2 | AK30: 0.172 | AL30: 0.12748743 | AM30: 3.4 | AN30: 3.4 | AO30: 3.8251433 | AP30: 6.6 | AQ30: 3.7749968 | AR30: 5.0146267 | AS30: =-52.21+16.22*AK30*100-1.25*(100*AK30)^2+0.05*(100*AK30)^3-0.000712*(100*AK30)^4 -> 49.08123 | AT30: =-52.21+16.22*AL30*100-1.25*(100*AL30)^2+0.05*(100*AL30)^3-0.000712*(100*AL30)^4 -> 36.2062 | AU30: =-0.164+6.73*AR30+2.87*AQ30^2 -> 74.483661
A31: 33 | B31: 95 | C31: 0.1852 | D31: 264.3 | E31: 125.36536 | F31: 2 | G31: iPhone 16e | H31: 10 | I31: 19 | J31: 35.085356 | K31: -120.53557 | L31: 82 | M31: 2026/08/21 14:25:50.065 | N31: fb2ec35d-761e-4f07-91f5-c0c9b322a18d | O31: 6.7 | Q31: 15.8 | AF31: 2026/08/21 14:27:23.851 | AG31: hosteen@calpoly.edu_CalPoly | AH31: 2026/08/21 14:27:23.851 | AI31: hosteen@calpoly.edu_CalPoly | AJ31: 15.8 | AK31: 0.158 | AL31: 0.080709552 | AN31: 3.4 | AO31: 3.7085984 | AP31: 6.7 | AQ31: 3.4700029 | AR31: 4.8204379 | AS31: =-52.21+16.22*AK31*100-1.25*(100*AK31)^2+0.05*(100*AK31)^3-0.000712*(100*AK31)^4 -> 44.859668 | AT31: =-52.21+16.22*AL31*100-1.25*(100*AL31)^2+0.05*(100*AL31)^3-0.000712*(100*AL31)^4 -> 20.541524 | AU31: =-0.164+6.73*AR31+2.87*AQ31^2 -> 66.834988
A32: 34 | B32: 96 | C32: 0.1852 | D32: 10.5 | E32: 81.264046 | F32: 2 | G32: iPhone 16e | H32: 10 | I32: 19 | J32: 35.085386 | K32: -120.53553 | L32: 82 | M32: 2026/08/21 14:28:37.082 | N32: 23037928-c450-43a9-8dad-efa22f453830 | O32: 6.8 | AF32: 2026/08/21 14:29:52.090 | AG32: hosteen@calpoly.edu_CalPoly | AH32: 2026/08/21 14:29:52.090 | AI32: hosteen@calpoly.edu_CalPoly | AK32: 0.2 | AL32: 0.16823634 | AN32: 3.3 | AO32: 3.8265657 | AP32: 6.8 | AQ32: 3.4790003 | AR32: 4.8204379 | AS32: =-52.21+16.22*AK32*100-1.25*(100*AK32)^2+0.05*(100*AK32)^3-0.000712*(100*AK32)^4 -> 58.27 | AT32: =-52.21+16.22*AL32*100-1.25*(100*AL32)^2+0.05*(100*AL32)^3-0.000712*(100*AL32)^4 -> 47.922259 | AU32: =-0.164+6.73*AR32+2.87*AQ32^2 -> 67.014429
A33: 35 | B33: 98 | C33: 0.3704 | D33: 125 | E33: 160.97415 | F33: 2 | G33: iPhone 16e | H33: 10 | I33: 19 | J33: 35.085268 | K33: -120.53554 | L33: 82.6 | M33: 2026/08/21 14:37:53.070 | N33: 353b7d79-2a06-4f2e-83d6-47f592913e94 | O33: 6.11 | Q33: 15.8 | AF33: 2026/08/21 14:38:01.734 | AG33: hosteen@calpoly.edu_CalPoly | AH33: 2026/08/21 14:39:39.959 | AI33: hosteen@calpoly.edu_CalPoly | AJ33: 15.8 | AK33: 0.158 | AL33: 0.14404346 | AN33: 3.2 | AO33: 4.007997 | AP33: 6.11 | AQ33: 3.7129991 | AR33: 4.6865107 | AS33: =-52.21+16.22*AK33*100-1.25*(100*AK33)^2+0.05*(100*AK33)^3-0.000712*(100*AK33)^4 -> 44.859668 | AT33: =-52.21+16.22*AL33*100-1.25*(100*AL33)^2+0.05*(100*AL33)^3-0.000712*(100*AL33)^4 -> 40.85476 | AU33: =-0.164+6.73*AR33+2.87*AQ33^2 -> 70.943077
A34: 36 | B34: 99 | C34: 0.3704 | D34: 178.6 | E34: 167.88144 | F34: 2 | G34: iPhone 16e | H34: 10 | I34: 19 | J34: 35.085243 | K34: -120.53558 | L34: 80.6 | M34: 2026/08/21 14:41:05.072 | N34: d3ecc0cc-2f4c-4ca7-9a85-f9bd86db15bb | O34: 6.10 | AF34: 2026/08/21 14:41:22.716 | AG34: hosteen@calpoly.edu_CalPoly | AH34: 2026/08/21 14:41:22.716 | AI34: hosteen@calpoly.edu_CalPoly | AK34: 0.161 | AL34: 0.087618261 | AN34: 3 | AO34: 3.4749382 | AP34: 6.10 | AQ34: 3.379003 | AR34: 4.5135167 | AS34: =-52.21+16.22*AK34*100-1.25*(100*AK34)^2+0.05*(100*AK34)^3-0.000712*(100*AK34)^4 -> 45.744395 | AT34: =-52.21+16.22*AL34*100-1.25*(100*AL34)^2+0.05*(100*AL34)^3-0.000712*(100*AL34)^4 -> 23.380694 | AU34: =-0.164+6.73*AR34+2.87*AQ34^2 -> 62.980656
A35: 37 | B35: 100 | C35: 0.1852 | D35: 12.5 | E35: 82.001945 | F35: 2 | G35: iPhone 16e | H35: 10 | I35: 19 | J35: 35.085304 | K35: -120.53549 | L35: 83.3 | M35: 2026/08/21 14:43:18.105 | N35: 3cbb2558-4394-4ade-a387-3686a60296f3 | O35: 6.12 | Q35: 16 | AF35: 2026/08/21 14:43:47.572 | AG35: hosteen@calpoly.edu_CalPoly | AH35: 2026/08/21 14:43:47.572 | AI35: hosteen@calpoly.edu_CalPoly | AJ35: 16 | AK35: 0.16 | AL35: 0.14121236 | AN35: 3.3 | AO35: 3.6420338 | AP35: 6.12 | AQ35: 3.5170021 | AR35: 5.232079 | AS35: =-52.21+16.22*AK35*100-1.25*(100*AK35)^2+0.05*(100*AK35)^3-0.000712*(100*AK35)^4 -> 45.448368 | AT35: =-52.21+16.22*AL35*100-1.25*(100*AL35)^2+0.05*(100*AL35)^3-0.000712*(100*AL35)^4 -> 40.05809 | AU35: =-0.164+6.73*AR35+2.87*AQ35^2 -> 70.547793
A36: 38 | B36: 101 | C36: 0 | D36: 333 | E36: 338.11356 | F36: 2 | G36: iPhone 16e | H36: 10 | I36: 19 | J36: 35.085331 | K36: -120.53547 | L36: 82.9 | M36: 2026/08/21 14:45:28.076 | N36: 6430207c-b0f6-45f9-af7d-b4046fd6c51c | O36: 6.13 | Q36: 18.5 | AF36: 2026/08/21 14:46:59.978 | AG36: hosteen@calpoly.edu_CalPoly | AH36: 2026/08/21 14:46:59.978 | AI36: hosteen@calpoly.edu_CalPoly | AJ36: 18.5 | AK36: 0.185 | AL36: 0.067364603 | AN36: 2.9 | AO36: 3.2874351 | AP36: 6.13 | AQ36: 3.3880029 | AR36: 4.6865107 | AS36: =-52.21+16.22*AK36*100-1.25*(100*AK36)^2+0.05*(100*AK36)^3-0.000712*(100*AK36)^4 -> 53.228586 | AT36: =-52.21+16.22*AL36*100-1.25*(100*AL36)^2+0.05*(100*AL36)^3-0.000712*(100*AL36)^4 -> 14.149262 | AU36: =-0.164+6.73*AR36+2.87*AQ36^2 -> 64.319694
A37: 39 | B37: 104 | C37: 0 | D37: 131.2 | E37: 172.61284 | F37: 2 | G37: iPhone 16e | H37: 10 | I37: 19 | J37: 35.085238 | K37: -120.53549 | L37: 82.6 | M37: 2026/08/21 14:57:43.082 | N37: f4bc578e-79e8-43e9-812a-4c6e26d1093f | O37: 6.16 | AF37: 2026/08/21 14:58:41.198 | AG37: hosteen@calpoly.edu_CalPoly | AH37: 2026/08/21 14:58:41.198 | AI37: hosteen@calpoly.edu_CalPoly | AK37: 0.167 | AL37: 0.14090268 | AN37: 3.6 | AO37: 4.243187 | AP37: 6.16 | AQ37: 3.8409994 | AR37: 4.8860251 | AS37: =-52.21+16.22*AK37*100-1.25*(100*AK37)^2+0.05*(100*AK37)^3-0.000712*(100*AK37)^4 -> 47.545552 | AT37: =-52.21+16.22*AL37*100-1.25*(100*AL37)^2+0.05*(100*AL37)^3-0.000712*(100*AL37)^4 -> 39.971129 | AU37: =-0.164+6.73*AR37+2.87*AQ37^2 -> 75.060852
A38: 40 | B38: 105 | C38: 0.3704 | D38: 170.7 | E38: 98.370789 | F38: 2 | G38: iPhone 16e | H38: 10 | I38: 19 | J38: 35.085267 | K38: -120.53545 | L38: 82.6 | M38: 2026/08/21 15:00:25.072 | N38: 41ea2dce-369d-4e54-8e57-840f2ccdf760 | O38: 6.17 | AF38: 2026/08/21 15:01:18.190 | AG38: hosteen@calpoly.edu_CalPoly | AH38: 2026/08/21 15:01:18.190 | AI38: hosteen@calpoly.edu_CalPoly | AK38: 0.175 | AL38: 0.13697925 | AN38: 3.5 | AO38: 3.6275227 | AP38: 6.17 | AQ38: 3.7029974 | AR38: 4.8204379 | AS38: =-52.21+16.22*AK38*100-1.25*(100*AK38)^2+0.05*(100*AK38)^3-0.000712*(100*AK38)^4 -> 50.018437 | AT38: =-52.21+16.22*AL38*100-1.25*(100*AL38)^2+0.05*(100*AL38)^3-0.000712*(100*AL38)^4 -> 38.871335 | AU38: =-0.164+6.73*AR38+2.87*AQ38^2 -> 71.631533
A39: 41 | B39: 187 | C39: 0 | D39: 137.7 | E39: 85.400421 | F39: 2 | G39: iPhone 16e | H39: 10 | I39: 19 | J39: 35.085422 | K39: -120.53558 | L39: 82 | M39: 2026/10/04 10:08:32.058 | N39: dc6ccdd4-0e50-4c57-850f-1e084edf8623 | O39: 6.a | Q39: 15.9 | AF39: 2026/10/04 10:10:27.519 | AG39: hosteen@calpoly.edu_CalPoly | AH39: 2026/10/04 10:10:27.519 | AI39: hosteen@calpoly.edu_CalPoly | AJ39: 15.9 | AK39: 0.159 | AL39: 0.12441779 | AN39: 2.8 | AO39: 3.3390048 | AP39: 6.a | AQ39: 3.1380017 | AR39: 4.7539459 | AS39: =-52.21+16.22*AK39*100-1.25*(100*AK39)^2+0.05*(100*AK39)^3-0.000712*(100*AK39)^4 -> 45.153468 | AT39: =-52.21+16.22*AL39*100-1.25*(100*AL39)^2+0.05*(100*AL39)^3-0.000712*(100*AL39)^4 -> 35.335152 | AU39: =-0.164+6.73*AR39+2.87*AQ39^2 -> 60.091103
A40: 42 | B40: 188 | C40: 0 | D40: 145.1 | E40: 176.32547 | F40: 2 | G40: iPhone 16e | H40: 10 | I40: 19 | J40: 35.085419 | K40: -120.53547 | L40: 83.1 | M40: 2026/10/04 10:12:26.073 | N40: 62ed4a29-4fd8-4b65-b78c-7b31965e62b5 | O40: 6.b | Q40: 20 | AF40: 2026/10/04 10:14:16.240 | AG40: hosteen@calpoly.edu_CalPoly | AH40: 2026/10/04 10:14:16.240 | AI40: hosteen@calpoly.edu_CalPoly | AJ40: 20 | AK40: 0.2 | AL40: 0.081230245 | AN40: 3.4 | AO40: 3.6613002 | AP40: 6.b | AQ40: 3.4640019 | AR40: 5.2015709 | AS40: =-52.21+16.22*AK40*100-1.25*(100*AK40)^2+0.05*(100*AK40)^3-0.000712*(100*AK40)^4 -> 58.27 | AT40: =-52.21+16.22*AL40*100-1.25*(100*AL40)^2+0.05*(100*AL40)^3-0.000712*(100*AL40)^4 -> 20.765415 | AU40: =-0.164+6.73*AR40+2.87*AQ40^2 -> 69.28059
...

Sheet Sheet2
B3: ​ | C3: Aboveground Biomass (kg/m²)​
B4: Footprint​ | C4: Manual​ | D4: WT App​ | E4: Drone LiDAR | F4: Backpack | G4: Drone RGB​ | H4: GEDI​
B5: 1​ | C5: =Sheet1!BE56 -> 1.5261881 | D5: =Sheet1!BF56 -> 1.3356577 | E5: =Sheet1!BG56 -> 1.9668426 | F5: ​ | G5: ​ | H5: 1.006​
B6: 2​ | C6: =Sheet1!BE71 -> 1.4356128 | D6: =Sheet1!BF71 -> 1.2613974 | E6: =Sheet1!BG71 -> 1.9350835 | F6: ​ | G6: ​ | H6: 1.151​
B7: 3​ | C7: =Sheet1!BE2 -> 1.2934455 | D7: =Sheet1!BF2 -> 1.1031792 | E7: =Sheet1!BG2 -> 1.4086669 | F7: ​ | G7: ​ | H7: 1.208​
B8: 4​ | C8: =Sheet1!BE15 -> 1.460459 | D8: =Sheet1!BF15 -> 1.2497402 | E8: =Sheet1!BG15 -> 1.695587 | F8: ​ | G8: ​ | H8: 1.052​
B9: 5​ | C9: =Sheet1!BE28 -> 1.4261853 | D9: =Sheet1!BF28 -> 1.0123342 | E9: =Sheet1!BG28 -> 1.9538925 | F9: ​ | G9: ​ | H9: 1.023​
B10: 6​ | C10: =Sheet1!BE42 -> 1.404265 | D10: =Sheet1!BF42 -> 1.1893767 | E10: =Sheet1!BG42 -> 1.9220669 | F10: ​ | G10: ​ | H10: 0.944​
B11: 7​ | C11: =Sheet1!BE84 -> 0.17821602 | D11: =Sheet1!BF84 -> -0.010162047 | E11: =Sheet1!BG84 -> 0.82415289 | F11: ​ | G11: ​ | H11: 1.061​
B12: 8​ | C12: =Sheet1!BE99 -> -0.85089071 | D12: =Sheet1!BF99 -> -0.85089071 | E12: =Sheet1!BG99 -> -0.0026727845 | F12: ​ | G12: ​ | H12: 1.070​
B13: 9​ | C13: =Sheet1!BE107 -> 1.4385065 | D13: =Sheet1!BF107 -> 1.3883826 | E13: =Sheet1!BG107 -> 1.7132821 | F13: ​ | G13: ​ | H13: 3.870​
B14: 10​ | C14: =Sheet1!BE121 -> 1.5355661 | D14: =Sheet1!BF121 -> 1.3033169 | E14: =Sheet1!BG121 -> 1.9796003 | F14: ​ | G14: ​ | H14: 1.118​
